Workbook

Sheet 引合書 (値引きなし）
A1: （様式：EL-97A03） | V1: 納入先コード | W1: 納入先カナ名 | X1: 納入先正式名 | Y1: 郵便番号1 | Z1: 住所1 | AA1: 電話番号1-1
A2: 引き合い内容連絡書 | J2: 株式会社オーレック | V2: 61102 | W2: ﾆﾎﾝｸﾘﾝﾄﾝ | X2: 日本クリントン㈱ | Y2: 121-0836 | Z2: 東京都 足立区 入谷5-7-8 | AA2: 03-3854-8221
A3: 得意先NO： | B3: 得意先名 及び 担当者名： | I3: 受注日： | V3: 61103 | W3: ﾄｳｺｳｻﾝｷﾞｮｳ | X3: 東興産業㈱ | Y3: 350-0821 | Z3: 埼玉県 川越市 福田239 | AA3: 0492-23-1217
A4: 61377 | C4: =IFERROR(VLOOKUP(A4,請求先!A:D,2,FALSE)," ") -> 千葉県農業機械商業協同組合 | I4: 46199 | L4: 製品コード検索 | V4: 61105 | W4: ｲﾄｳｻﾝｷﾞｮｳｷｶｲ | X4: 伊藤産業機械㈱ | Y4: 290-0034 | Z4: 千葉県 市原市 島野1978 | AA4: 0436-22-1743
A5: 納入先NO： | B5: 納入先名及び 担当者名： | G5: 生産日 | H5: 46226 | I5: 出荷希望日： | L5: WM746F?M | Q5: → | R5: =IFERROR(VLOOKUP(L5,商品コード!B:F,5,FALSE)," ") -> 0317-0320 | V5: 61106 | W5: ｴﾑｴｽｹｰﾉｳｷﾞｮｳｷｶｲﾁﾊﾞｼﾞｷﾞｮｳｼｮ | X5: MSK東急機械㈱ 千葉事業所 | Y5: 290-0012 | Z5: 千葉県 市原市 藤井3-310 | AA5: 0436-41-1069
A6: 61313 | C6: =IFERROR(VLOOKUP(A6,出荷先!A:F,3,FALSE)," ") -> ㈲鈴木農機 | I6: 46230 | V6: 61107 | W6: ｻｻｷｼｮｳｶｲ | X6: ㈱佐々木商会 | Y6: 294-0037 | Z6: 千葉県 館山市 長須賀123 | AA6: 0470-22-1166
B7: 住所： | C7: 〒 | D7: =IFERROR(VLOOKUP(A6,出荷先!A:F,4,FALSE)," ") -> 283-0046 | I7: TEL | L7: 不需要期値引 | Q7: =IF(Q6="","",VLOOKUP(Q6,#REF!,2,FALSE)) | V7: 61108 | W7: ｽｷﾞｷﾃｯｺｳ | X7: 杉木鉄工㈱ | Y7: 297-0029 | Z7: 千葉県 茂原市 高師1536 | AA7: 0475-22-4587
B8: =IFERROR(VLOOKUP(A6,出荷先!A:F,5,FALSE)," ") -> 千葉県 東金市 上谷956 | I8: =IFERROR(VLOOKUP(A6,出荷先!A:F,6,FALSE)," ") -> 0475-52-4511 | L8: =IF(L7="","",VLOOKUP(L7,商品コード!A:B,2,FALSE)) -> 内掛 | M8: =IF(I8="","",VLOOKUP(I8,商品コード!#REF!,2,FALSE)) -> #REF! | N8: 5 | P8: % | V8: 61109 | W8: ﾀｶﾉｻﾝｷﾞｮｳ | X8: 高野産業㈱ | Y8: 292-0054 | Z8: 千葉県 木更津市 長須賀924-1 | AA8: 0438-22-6251
V9: 61110 | W9: ｶﾝﾄｳｺｼﾝｸﾎﾞﾀﾁﾊﾞｼﾞｷﾞｮｳﾌﾞ | X9: ㈱関東甲信クボタ 南関東事業所 | Y9: 260-0808 | Z9: 千葉県 千葉市 中央区 星久喜町176-4 | AA9: 043-261-3131
A10: 商品番号 | B10: 商品名 | E10: 数量 | F10: 単位 | G10: 単価 | I10: オーダーＮｏ 等 | L10: 税別小売 | N10: 通常 | P10: =IF(A4="","",VLOOKUP(A4,請求先!A:D,4,FALSE)) -> 0.67 | Q10: 値引 | R10: =$N$8/100 -> 0.05 | S10: 最終 | T10: =IF(L8="外掛",P10-R10,IF(L8="内掛",ROUNDDOWN(P10*(100-100*R10)%,5))) -> 0.6365 | V10: 61111 | W10: ﾅｶﾔｼｮｳｶｲ | X10: ㈱中屋商会 | Y10: 289-2146 | Z10: 千葉県 匝瑳市 八日市場ホ452 | AA10: 0479-72-1161
A11: 0353-0020 | B11: =IFERROR(VLOOKUP(A11,商品コード!A:C,2,FALSE)," ") -> SP753B/M | E11: 1 | L11: =IF(A11="","",VLOOKUP(A11,商品コード!A:C,3,FALSE)) -> 328000 | N11: =IFERROR(IF(A4=61121,ROUNDDOWN((L11*P10),-1),IF(A4=61123,ROUNDDOWN((L11*P10),-1),IF(A4=64445001,ROUNDDOWN((L11*P10),-1),IF(A4=64445002,ROUNDDOWN((L11*P10),-1),ROUNDDOWN(L11*P10,-2)))))," ") -> 219700 | Q11: =IFERROR(S11-N11," ") -> -11000 | S11: =IFERROR(IF(OR(A4=61121,A4=61123,A4=64445001,A4=64445002),IF(L8="内掛",ROUNDDOWN(N11*(1-R10),-1),ROUNDDOWN(L11*T10,-1)),IF(L8="内掛",ROUNDDOWN(N11*(1-R10),-2),ROUNDDOWN(L11*T10,-2)))," ") -> 208700 | V11: 61112 | W11: ﾅｶﾑﾗｻﾝｷﾞｮｳ | X11: ㈱中村産業 | Y11: 283-0811 | Z11: 千葉県 東金市 台方246 | AA11: 0475-52-2615
B12: =IFERROR(VLOOKUP(A12,商品コード!A:C,2,FALSE)," ") | L12: =IF(A12="","",VLOOKUP(A12,商品コード!A:C,3,FALSE)) | N12: =IFERROR(IF(A4=61121,ROUNDDOWN((L12*P10),-1),IF(A4=61123,ROUNDDOWN((L12*P10),-1),IF(A4=64445001,ROUNDDOWN((L12*P10),-1),IF(A4=64445002,ROUNDDOWN((L12*P10),-1),ROUNDDOWN(L12*P10,-2)))))," ") | Q12: =IFERROR(S12-N12," ") | S12: =IFERROR(IF(OR(A4=61121,A4=61123,A4=64445001,A4=64445002),IF(L8="内掛",ROUNDDOWN(N12*(1-R10),-1),ROUNDDOWN(L12*T10,-1)),IF(L8="内掛",ROUNDDOWN(N12*(1-R10),-2),ROUNDDOWN(L12*T10,-2)))," ") | V12: 61113 | W12: ﾌﾀﾊﾞｺｳｷ | X12: ㈲双葉工機 | Y12: 270-2222 | Z12: 千葉県 松戸市 高塚新田340-11 | AA12: 0473-92-7256
B13: =IFERROR(VLOOKUP(A13,商品コード!A:C,2,FALSE)," ") | L13: =IF(A13="","",VLOOKUP(A13,商品コード!A:C,3,FALSE)) | N13: =IFERROR(IF(A4=61121,ROUNDDOWN((L13*P10),-1),IF(A4=61123,ROUNDDOWN((L13*P10),-1),IF(A4=64445001,ROUNDDOWN((L13*P10),-1),IF(A4=64445002,ROUNDDOWN((L13*P10),-1),ROUNDDOWN(L13*P10,-2)))))," ") | Q13: =IFERROR(S13-N13," ") | S13: =IFERROR(IF(OR(A4=61121,A4=61123,A4=64445001,A4=64445002),IF(L8="内掛",ROUNDDOWN(N13*(1-R10),-1),ROUNDDOWN(L13*T10,-1)),IF(L8="内掛",ROUNDDOWN(N13*(1-R10),-2),ROUNDDOWN(L13*T10,-2)))," ") | V13: 61114 | W13: ﾓﾊﾞﾗﾌｺｸｼｬ | X13: ㈱茂原富国社 | Y13: 297-0029 | Z13: 千葉県 茂原市 高師1671 | AA13: 0475-25-0325
B14: =IFERROR(VLOOKUP(A14,商品コード!A:C,2,FALSE)," ") | L14: =IF(A14="","",VLOOKUP(A14,商品コード!A:C,3,FALSE)) | N14: =IFERROR(IF(A4=61121,ROUNDDOWN((L14*P10),-1),IF(A4=61123,ROUNDDOWN((L14*P10),-1),IF(A4=64445001,ROUNDDOWN((L14*P10),-1),IF(A4=64445002,ROUNDDOWN((L14*P10),-1),ROUNDDOWN(L14*P10,-2)))))," ") | Q14: =IFERROR(S14-N14," ") | S14: =IFERROR(IF(OR(A4=61121,A4=61123,A4=64445001,A4=64445002),IF(L8="内掛",ROUNDDOWN(N14*(1-R10),-1),ROUNDDOWN(L14*T10,-1)),IF(L8="内掛",ROUNDDOWN(N14*(1-R10),-2),ROUNDDOWN(L14*T10,-2)))," ") | V14: 61115 | W14: ｲﾊﾞﾗｷﾘｮｳﾉｳ | X14: 茨城菱農㈱ | Y14: 300-4201 | Z14: 茨城県 つくば市 寺具1332-9 | AA14: 0298-69-1045
B15: =IFERROR(VLOOKUP(A15,商品コード!A:C,2,FALSE)," ") | V15: 61116 | W15: ｶﾝﾄｳｺｳｼﾝｸﾎﾞﾀｲﾊﾞﾗｷｼﾞﾑｼｮ | X15: ㈱関東甲信クボタ 茨城事務所 | Y15: 300-2402 | Z15: 茨城県 つくばみらい市 坂野新田12-42 | AA15: 0297-52-1111
B16: =IFERROR(VLOOKUP(A16,商品コード!A:C,2,FALSE)," ") | V16: 61117 | W16: ｵｵｶﾜｷｶｲ | X16: 大川機械 | Y16: 300-0024 | Z16: 茨城県 土浦市 田村町988-2 | AA16: 0298-28-0755
A17: 倉庫（ | B17: 011 | C17: ） | D17: 運賃 | E17: 元払い | F17: 伝票NO： | V17: 61118 | W17: ﾐﾂﾋﾞｼﾉｳｷﾊﾝﾊﾞｲｲﾊﾞﾗｷｼﾃﾝ | X17: 三菱農機販売㈱ 茨城支店 | Y17: 311-0133 | Z17: 茨城県 那珂市 鴻巣1135-1 | AA17: 0293-53-2140
B18: 0 | E18: 立 元 | F18: 出荷確認 | H18: 受注可否検討 | J18: 連絡書作成 | V18: 61120 | W18: ｼﾏｻﾉｳｷ | X18: ㈱嶋田農機 | Y18: 300-3544 | Z18: 茨城県 結城郡 八千代町 若996 | AA18: 0296-48-1025
E19: 着払い | F19: 承認 | H19: 承認 | J19: 作成者 | V19: 61121 | W19: ｸﾎﾞﾀｲﾊﾞﾗｷｹﾝｴｲｷﾞｮｳﾀﾝﾄｳ | X19: ㈱クボタ 茨城県営業担当 | Y19: 338-0832 | Z19: 埼玉県 さいたま市 桜区 西堀5-2-36 | AA19: 048-862-1125
C20: 便名： | D20: 福山便 西濃便 JPロジ | V20: 61122 | W20: ﾅﾘﾀｶﾄｳﾉｳｷ | X20: 成田加藤農機（有） | Y20: 286-0021 | Z20: 千葉県 成田市 土屋1375-1 | AA20: 0476-22-0579
V21: 61123 | W21: ｸﾎﾞﾀﾄﾁｷﾞｹﾝｴｲｷﾞｮｳﾀﾝﾄｳ | X21: ㈱クボタ 栃木県営業担当 | Y21: 338-0832 | Z21: 埼玉県 さいたま市 桜区 西堀5-2-36 | AA21: 048-862-1125
V22: 61124 | W22: ﾈﾓﾄｼｮｳｶｲ | X22: ㈲根本商会 | Y22: 286-0801 | Z22: 千葉県 成田市 竜台468 | AA22: 0476-37-1211
A23: 製品コード検索 | V23: 61125 | W23: ﾏﾙﾃﾝｻﾝｷﾞｮｳｷｶｲ | X23: マルテン産業機械㈱ | Y23: 293-0001 | Z23: 千葉県 富津市 大堀1434 | AA23: 0439-87-0052
A24: RCSP530/Y | F24: → | G24: =IFERROR(VLOOKUP(A24,商品コード!B:F,5,FALSE)," ") | V24: 61126 | W24: ﾐﾂﾋﾞｼﾉｳｷﾊﾝﾊﾞｲﾁﾊﾞｼﾃﾝ | X24: 三菱農機販売㈱ 千葉支店 | Y24: 300-1312 | Z24: 茨城県 稲敷郡 河内町 長竿字西の町1596-2 | AA24: 0297-63-4633
V25: 61127 | W25: ｸﾎﾞﾀｸﾞﾝﾏｹﾝｴｲｷﾞｮｳﾀﾝﾄｳ | X25: ㈱クボタ 群馬県営業担当 | Y25: 338-0832 | Z25: 埼玉県 さいたま市 桜区 西堀5-2-36 | AA25: 048-862-1125
V26: 61133 | W26: ﾏｷﾀﾇﾏﾂﾞﾋｶﾞｼﾆﾎﾝ | X26: ㈱マキタ沼津 東日本支店 | Y26: 362-0031 | Z26: 埼玉県 上尾市 東町2-8-4 | AA26: 048-779-2262
V27: 61134 | W27: ｸﾎﾞﾀｹﾝｷｼﾞｬﾊﾟﾝﾁﾊﾞｴｲｷﾞｮｳｼｮ | X27: ㈱クボタ建機ジャパン千葉営業所 | Y27: 283-0823 | Z27: 千葉県 東金市 山田 字新田1201-10 | AA27: 茨城菱農
V28: 61135 | W28: ｵｵｻﾜｷｶｲ | X28: 大沢機械 | Y28: 191-0043 | Z28: 東京都 日野市 平山6-2-1 | AA28: 042-591-1588
V29: 61136 | W29: ｼﾊﾞﾀ | X29: ㈱シバタ | Y29: 104-0032 | Z29: 東京都 中央区 八丁堀4-3-1 | AA29: 03-3552-0381
V30: 61140 | W30: ﾏｷﾀﾇﾏﾂﾞｷﾞｮｳﾑﾌﾞｼｮｳﾋﾝｶ | X30: ㈱マキタ沼津 業務部商品課 | Y30: 410-0022 | Z30: 静岡県 沼津市 大岡35 | AA30: 055-963-1112
V31: 61301 | W31: ｶﾅｴｻﾝｷﾞｮｳ | X31: カナエ産業㈱ | Y31: 194-0215 | Z31: 東京都 町田市 小山ケ丘3-7-10 | AA31: 042-798-7181
V32: 61302 | W32: ﾖｼｻﾞﾜｹﾞﾝﾄﾞｳｷ | X32: 吉澤原動機 | Y32: 114-0013 | Z32: 東京都 北区 東田端2-8-6 | AA32: 03-3810-2700
V33: 61303 | W33: ﾐﾔｼﾞｷｶｲ | X33: ㈱宮地機械（出荷停止） | Y33: 177-0033 | Z33: 東京都 練馬区 高野台4-11-28 | AA33: 03-3997-3155
V34: 61304 | W34: ﾊﾁｷﾞｮｳｼｮｳｼﾞ | X34: 八丈商事 | Y34: 100-1401 | Z34: 東京都 八丈島 八丈町 大賀郷1098-2 | AA34: 04996-2-2189
V35: 61305 | W35: ｲｼｲﾃﾞﾝｷｼｮｳﾃﾝ | X35: ㈱石井電気商店 | Y35: 294-0042 | Z35: 千葉県 館山市 上野原294-5 | AA35: 0470-22-0542
V36: 61306 | W36: ｲｺﾞｳﾉｳｷ | X36: ㈲井合農機店 | Y36: 273-0047 | Z36: 千葉県 船橋市 藤原5-22-31 | AA36: 047-439-5477
... V95: 61376 | W95: ﾘｮｳｴｲｼｬ | X95: ㈲良栄社商会 | Y95: 299-1151 | Z95: 千葉県 君津市 中野4-15-18 | AA95: 0439-52-0035
W96: ｺｼﾞﾝｷｬｸ | X96: 個人客
V97: 61400 | W97: ｺﾐﾔﾉｳｻﾝｷｼｮｳｶｲ | X97: ㈲古宮農蚕機商会 | Y97: 192-0051 | Z97: 東京都 八王子市 元本郷町1-5-5 | AA97: 042-625-2328
V98: 63102 | W98: ﾐﾂﾋﾞｼﾉｳｷﾊﾝﾊﾞｲｶﾝﾄｳｺｳｼﾝｴﾂ | X98: 三菱農機販売㈱ 関東甲信越支店 | Y98: 340-0203 | Z98: 埼玉県 久喜市 桜田2-133-4 | AA98: 0480-58-9521
...

Sheet 実演機分
A1: （様式：EL-97A03） | W1: 納入先コード | X1: 納入先カナ名 | Y1: 納入先正式名 | Z1: 郵便番号1 | AA1: 住所1 | AB1: 電話番号1-1
A2: 引き合い内容連絡書 | J2: 株式会社オーレック | W2: 61102 | X2: ﾆﾎﾝｸﾘﾝﾄﾝ | Y2: 日本クリントン㈱ | Z2: 121-0836 | AA2: 東京都 足立区 入谷5-7-8 | AB2: 03-3854-8221
A3: 得意先NO： | B3: 得意先名 及び 担当者名： | I3: 受注日： | W3: 61103 | X3: ﾄｳｺｳｻﾝｷﾞｮｳ | Y3: 東興産業㈱ | Z3: 350-0821 | AA3: 埼玉県 川越市 福田239 | AB3: 0492-23-1217
A4: 61125 | C4: =IFERROR(VLOOKUP(A4,請求先!A:D,2,FALSE)," ") -> マルテン産業機械㈱ | I4: 46199 | L4: 製品コード検索 | W4: 61105 | X4: ｲﾄｳｻﾝｷﾞｮｳｷｶｲ | Y4: 伊藤産業機械㈱ | Z4: 290-0034 | AA4: 千葉県 市原市 島野1978 | AB4: 0436-22-1743
A5: 納入先NO： | B5: 納入先名及び 担当者名： | G5: 生産日 | I5: 出荷希望日： | L5: RM984X/K | Q5: → | R5: =IFERROR(VLOOKUP(L5,商品コード!B:F,5,FALSE)," ") -> 0352-0110 | W5: 61106 | X5: ｴﾑｴｽｹｰﾉｳｷﾞｮｳｷｶｲﾁﾊﾞｼﾞｷﾞｮｳｼｮ | Y5: MSK東急機械㈱ 千葉事業所 | Z5: 290-0012 | AA5: 千葉県 市原市 藤井3-310 | AB5: 0436-41-1069
A6: 61125 | C6: =IFERROR(VLOOKUP(A6,出荷先!A:F,3,FALSE)," ") -> マルテン産業機械㈱ | I6: 46199 | W6: 61107 | X6: ｻｻｷｼｮｳｶｲ | Y6: ㈱佐々木商会 | Z6: 294-0037 | AA6: 千葉県 館山市 長須賀123 | AB6: 0470-22-1166
B7: 住所： | C7: 〒 | D7: =IFERROR(VLOOKUP(A6,出荷先!A:F,4,FALSE)," ") -> 293-0001 | I7: TEL | L7: 実演機値引 | Q7: =IF(Q6="","",VLOOKUP(Q6,#REF!,2,FALSE)) | W7: 61108 | X7: ｽｷﾞｷﾃｯｺｳ | Y7: 杉木鉄工㈱ | Z7: 297-0029 | AA7: 千葉県 茂原市 高師1536 | AB7: 0475-22-4587
B8: =IFERROR(VLOOKUP(A6,出荷先!A:F,5,FALSE)," ") -> 千葉県 富津市 大堀1434 | I8: =IFERROR(VLOOKUP(A6,出荷先!A:F,6,FALSE)," ") -> 0439-87-0052 | L8: =IF(L7="","",VLOOKUP(L7,商品コード!A:B,2,FALSE)) -> 外掛 | M8: =IF(I8="","",VLOOKUP(I8,商品コード!#REF!,2,FALSE)) -> #REF! | N8: 8 | P8: % | W8: 61109 | X8: ﾀｶﾉｻﾝｷﾞｮｳ | Y8: 高野産業㈱ | Z8: 292-0054 | AA8: 千葉県 木更津市 長須賀924-1 | AB8: 0438-22-6251
N9: ] | W9: 61110 | X9: ｶﾝﾄｳｺｼﾝｸﾎﾞﾀﾁﾊﾞｼﾞｷﾞｮｳﾌﾞ | Y9: ㈱関東甲信クボタ 南関東事業所 | Z9: 260-0808 | AA9: 千葉県 千葉市 中央区 星久喜町176-4 | AB9: 043-261-3131
A10: 商品番号 | B10: 商品名 | E10: 数量 | F10: 単位 | G10: 単価 | I10: オーダーＮｏ 等 | L10: 税別小売 | N10: 通常 | P10: =IF(A4="","",VLOOKUP(A4,請求先!A:D,4,FALSE)) -> 0.7 | Q10: 値引 | R10: =$N$8/100 -> 0.08 | S10: 最終 | T10: =IF(L8="外掛",P10-R10,IF(L8="内掛",ROUNDDOWN(P10*(100-100*R10)%,5))) -> 0.62 | W10: 61111 | X10: ﾅｶﾔｼｮｳｶｲ | Y10: ㈱中屋商会 | Z10: 289-2146 | AA10: 千葉県 匝瑳市 八日市場ホ452 | AB10: 0479-72-1161
A11: 0334-0420 | B11: =IFERROR(VLOOKUP(A11,商品コード!A:C,2,FALSE)," ") -> HRC665S/M (ｾﾙ仕様） | E11: 1 | G11: =O13 -> 0 | K11: → | L11: =IF(A11="","",VLOOKUP(A11,商品コード!A:C,3,FALSE)) -> 698000 | N11: =IFERROR(IF(A4=61121,ROUNDDOWN((L11*P10),-1),IF(A4=61123,ROUNDDOWN((L11*P10),-1),IF(A4=64445001,ROUNDDOWN((L11*P10),-1),IF(A4=64445002,ROUNDDOWN((L11*P10),-1),ROUNDDOWN(L11*P10,-2)))))," ") -> 488600 | Q11: =IFERROR(S11-N11," ") -> -55900 | S11: =IFERROR(IF(OR(A4=61121,A4=61123,A4=64445001,A4=64445002),IF(L8="内掛",ROUNDDOWN(N11*(1-R10),-1),ROUNDDOWN(L11*T10,-1)),IF(L8="内掛",ROUNDDOWN(N11*(1-R10),-2),ROUNDDOWN(L11*T10,-2)))," ") -> 432700 | W11: 61112 | X11: ﾅｶﾑﾗｻﾝｷﾞｮｳ | Y11: ㈱中村産業 | Z11: 283-0811 | AA11: 千葉県 東金市 台方246 | AB11: 0475-52-2615
B12: =IFERROR(VLOOKUP(A12,商品コード!A:C,2,FALSE)," ") | G12: =O14 -> 0 | K12: → | L12: =IF(A12="","",VLOOKUP(A12,商品コード!A:C,3,FALSE)) | N12: =IFERROR(IF(A4=61121,ROUNDDOWN((L12*P10),-1),IF(A4=61123,ROUNDDOWN((L12*P10),-1),IF(A4=64445001,ROUNDDOWN((L12*P10),-1),IF(A4=64445002,ROUNDDOWN((L12*P10),-1),ROUNDDOWN(L12*P10,-2)))))," ") | Q12: =IFERROR(S12-N12," ") | S12: =IFERROR(IF(OR(A4=61121,A4=61123,A4=64445001,A4=64445002),IF(L8="内掛",ROUNDDOWN(N12*(1-R10),-1),ROUNDDOWN(L12*T10,-1)),IF(L9="内掛",ROUNDDOWN(N12*(1-R10),-2),ROUNDDOWN(L12*T10,-2)))," ") | W12: 61113 | X12: ﾌﾀﾊﾞｺｳｷ | Y12: ㈲双葉工機 | Z12: 270-2222 | AA12: 千葉県 松戸市 高塚新田340-11 | AB12: 0473-92-7256
B13: =IFERROR(VLOOKUP(A13,商品コード!A:C,2,FALSE)," ") | G13: =O15 -> 0 | K13: → | L13: =IF(A13="","",VLOOKUP(A13,商品コード!A:C,3,FALSE)) | N13: =IFERROR(IF(A4=61121,ROUNDDOWN((L13*P10),-1),IF(A4=61123,ROUNDDOWN((L13*P10),-1),IF(A4=64445001,ROUNDDOWN((L13*P10),-1),IF(A4=64445002,ROUNDDOWN((L13*P10),-1),ROUNDDOWN(L13*P10,-2)))))," ") | Q13: =IFERROR(S13-N13," ") | S13: =IFERROR(IF(OR(A4=61121,A4=61123,A4=64445001,A4=64445002),IF(L8="内掛",ROUNDDOWN(N13*(1-R10),-1),ROUNDDOWN(L13*T10,-1)),IF(L10="内掛",ROUNDDOWN(N13*(1-R10),-2),ROUNDDOWN(L13*T10,-2)))," ") | W13: 61114 | X13: ﾓﾊﾞﾗﾌｺｸｼｬ | Y13: ㈱茂原富国社 | Z13: 297-0029 | AA13: 千葉県 茂原市 高師1671 | AB13: 0475-25-0325
B14: =IFERROR(VLOOKUP(A14,商品コード!A:C,2,FALSE)," ") | G14: =O16 -> 0 | K14: → | L14: =IF(A14="","",VLOOKUP(A14,商品コード!A:C,3,FALSE)) | N14: =IFERROR(IF(A4=61121,ROUNDDOWN((L14*P10),-1),IF(A4=61123,ROUNDDOWN((L14*P10),-1),IF(A4=64445001,ROUNDDOWN((L14*P10),-1),IF(A4=64445002,ROUNDDOWN((L14*P10),-1),ROUNDDOWN(L14*P10,-2)))))," ") | Q14: =IFERROR(S14-N14," ") | S14: =IFERROR(IF(OR(A4=61121,A4=61123,A4=64445001,A4=64445002),IF(L8="内掛",ROUNDDOWN(N14*(1-R10),-1),ROUNDDOWN(L14*T10,-1)),IF(L10="内掛",ROUNDDOWN(N14*(1-R10),-2),ROUNDDOWN(L14*T10,-2)))," ") | W14: 61115 | X14: ｲﾊﾞﾗｷﾘｮｳﾉｳ | Y14: 茨城菱農㈱ | Z14: 300-4201 | AA14: 茨城県 つくば市 寺具1332-9 | AB14: 0298-69-1045
B15: =IFERROR(VLOOKUP(A15,商品コード!A:C,2,FALSE)," ") | G15: =O17 -> 0 | L15: 生産日 | N15: 45870 | W15: 61116 | X15: ｶﾝﾄｳｺｳｼﾝｸﾎﾞﾀｲﾊﾞﾗｷｼﾞﾑｼｮ | Y15: ㈱関東甲信クボタ 茨城事務所 | Z15: 300-2402 | AA15: 茨城県 つくばみらい市 坂野新田12-42 | AB15: 0297-52-1111
B16: =IFERROR(VLOOKUP(A16,商品コード!A:C,2,FALSE)," ") | G16: =O18 -> 0 | W16: 61117 | X16: ｵｵｶﾜｷｶｲ | Y16: 大川機械 | Z16: 300-0024 | AA16: 茨城県 土浦市 田村町988-2 | AB16: 0298-28-0755
A17: 倉庫（ | B17: 2001 | C17: ） | D17: 運賃 | E17: 元払い | F17: 伝票NO： | W17: 61118 | X17: ﾐﾂﾋﾞｼﾉｳｷﾊﾝﾊﾞｲｲﾊﾞﾗｷｼﾃﾝ | Y17: 三菱農機販売㈱ 茨城支店 | Z17: 311-0133 | AA17: 茨城県 那珂市 鴻巣1135-1 | AB17: 0293-53-2140
A18: 納入済み 機番:JQBFB00062 | E18: 立 元 | F18: 出荷確認 | H18: 受注可否検討 | J18: 連絡書作成 | W18: 61120 | X18: ｼﾏｻﾉｳｷ | Y18: ㈱嶋田農機 | Z18: 300-3544 | AA18: 茨城県 結城郡 八千代町 若996 | AB18: 0296-48-1025
E19: 着払い | F19: 承認 | H19: 承認 | J19: 作成者 | W19: 61121 | X19: ｸﾎﾞﾀｲﾊﾞﾗｷｹﾝｴｲｷﾞｮｳﾀﾝﾄｳ | Y19: ㈱クボタ 茨城県営業担当 | Z19: 338-0832 | AA19: 埼玉県 さいたま市 桜区 西堀5-2-36 | AB19: 048-862-1125
C20: 便名： | D20: 福山便 西濃便 JPロジ | W20: 61122 | X20: ﾅﾘﾀｶﾄｳﾉｳｷ | Y20: 成田加藤農機（有） | Z20: 286-0021 | AA20: 千葉県 成田市 土屋1375-1 | AB20: 0476-22-0579
W21: 61123 | X21: ｸﾎﾞﾀﾄﾁｷﾞｹﾝｴｲｷﾞｮｳﾀﾝﾄｳ | Y21: ㈱クボタ 栃木県営業担当 | Z21: 338-0832 | AA21: 埼玉県 さいたま市 桜区 西堀5-2-36 | AB21: 048-862-1125
W22: 61124 | X22: ﾈﾓﾄｼｮｳｶｲ | Y22: ㈲根本商会 | Z22: 286-0801 | AA22: 千葉県 成田市 竜台468 | AB22: 0476-37-1211
A23: （様式：EL-97A03） | D23: 【 値引 】 | W23: 61125 | X23: ﾏﾙﾃﾝｻﾝｷﾞｮｳｷｶｲ | Y23: マルテン産業機械㈱ | Z23: 293-0001 | AA23: 千葉県 富津市 大堀1434 | AB23: 0439-87-0052
A24: 引き合い内容連絡書 | J24: 株式会社オーレック | W24: 61126 | X24: ﾐﾂﾋﾞｼﾉｳｷﾊﾝﾊﾞｲﾁﾊﾞｼﾃﾝ | Y24: 三菱農機販売㈱ 千葉支店 | Z24: 300-1312 | AA24: 茨城県 稲敷郡 河内町 長竿字西の町1596-2 | AB24: 0297-63-4633
A25: 得意先NO： | B25: 得意先名 及び 担当者名： | I25: 受注日： | W25: 61127 | X25: ｸﾎﾞﾀｸﾞﾝﾏｹﾝｴｲｷﾞｮｳﾀﾝﾄｳ | Y25: ㈱クボタ 群馬県営業担当 | Z25: 338-0832 | AA25: 埼玉県 さいたま市 桜区 西堀5-2-36 | AB25: 048-862-1125
A26: 61377 | C26: =C4 -> マルテン産業機械㈱ | I26: =I4 -> 46199 | W26: 61133 | X26: ﾏｷﾀﾇﾏﾂﾞﾋｶﾞｼﾆﾎﾝ | Y26: ㈱マキタ沼津 東日本支店 | Z26: 362-0031 | AA26: 埼玉県 上尾市 東町2-8-4 | AB26: 048-779-2262
A27: 納入先NO： | B27: 納入先名及び 担当者名： | I27: 出荷希望日： | W27: 61134 | X27: ｸﾎﾞﾀｹﾝｷｼﾞｬﾊﾟﾝﾁﾊﾞｴｲｷﾞｮｳｼｮ | Y27: ㈱クボタ建機ジャパン千葉営業所 | Z27: 283-0823 | AA27: 千葉県 東金市 山田 字新田1201-10 | AB27: 茨城菱農
A28: 69012068 | C28: =C6 -> マルテン産業機械㈱ | I28: =I6 -> 46199 | W28: 61135 | X28: ｵｵｻﾜｷｶｲ | Y28: 大沢機械 | Z28: 191-0043 | AA28: 東京都 日野市 平山6-2-1 | AB28: 042-591-1588
B29: 住所： | I29: TEL | W29: 61136 | X29: ｼﾊﾞﾀ | Y29: ㈱シバタ | Z29: 104-0032 | AA29: 東京都 中央区 八丁堀4-3-1 | AB29: 03-3552-0381
W30: 61140 | X30: ﾏｷﾀﾇﾏﾂﾞｷﾞｮｳﾑﾌﾞｼｮｳﾋﾝｶ | Y30: ㈱マキタ沼津 業務部商品課 | Z30: 410-0022 | AA30: 静岡県 沼津市 大岡35 | AB30: 055-963-1112
W31: 61301 | X31: ｶﾅｴｻﾝｷﾞｮｳ | Y31: カナエ産業㈱ | Z31: 194-0215 | AA31: 東京都 町田市 小山ケ丘3-7-10 | AB31: 042-798-7181
A32: 商品番号 | B32: 商品名 | E32: 数量 | F32: 値引後(仕切) | H32: 単価 | J32: 合計 | W32: 61302 | X32: ﾖｼｻﾞﾜｹﾞﾝﾄﾞｳｷ | Y32: 吉澤原動機 | Z32: 114-0013 | AA32: 東京都 北区 東田端2-8-6 | AB32: 03-3810-2700
A33: =A11 -> 0334-0420 | B33: =B11 -> HRC665S/M (ｾﾙ仕様） | E33: =E11 -> 1 | F33: =S11 -> 432700 | H33: =IFERROR(Q11," ") -> -55900 | J33: =IFERROR(H33*E33," ") -> -55900 | W33: 61303 | X33: ﾐﾔｼﾞｷｶｲ | Y33: ㈱宮地機械（出荷停止） | Z33: 177-0033 | AA33: 東京都 練馬区 高野台4-11-28 | AB33: 03-3997-3155
A34: =A12 -> 0 | B34: =B12 | E34: =E12 -> 0 | F34: =S12 | H34: =IFERROR(Q12," ") | J34: =IFERROR(H34*E34," ") | W34: 61304 | X34: ﾊﾁｷﾞｮｳｼｮｳｼﾞ | Y34: 八丈商事 | Z34: 100-1401 | AA34: 東京都 八丈島 八丈町 大賀郷1098-2 | AB34: 04996-2-2189
A35: =A13 -> 0 | E35: =E13 -> 0 | F35: =S13 | H35: =IFERROR(Q13," ") | J35: =IFERROR(H35*E35," ") | W35: 61305 | X35: ｲｼｲﾃﾞﾝｷｼｮｳﾃﾝ | Y35: ㈱石井電気商店 | Z35: 294-0042 | AA35: 千葉県 館山市 上野原294-5 | AB35: 0470-22-0542
A36: =A14 -> 0 | B36: =B14 | E36: =E14 -> 0 | F36: =S14 | H36: =IFERROR(Q14," ") | J36: =IFERROR(H36*E36," ") | W36: 61306 | X36: ｲｺﾞｳﾉｳｷ | Y36: ㈲井合農機店 | Z36: 273-0047 | AA36: 千葉県 船橋市 藤原5-22-31 | AB36: 047-439-5477
A37: =A15 -> 0 | B37: =B15 | E37: =E15 -> 0 | F37: =S15 -> 0 | H37: =IFERROR(-(S17)," ") -> 0 | J37: =IFERROR(H37*E37," ") -> 0 | W37: 61307 | X37: ｲｼｲﾃｯｺｳ | Y37: 石井鉄工㈱ | Z37: 299-4218 | AA37: 千葉県 長生郡 白子町 関4549-2 | AB37: 0475-33-3528
A38: =A16 -> 0 | B38: =B16 | E38: =E16 -> 0 | F38: =Q18 -> 0 | H38: =IFERROR(-(S18)," ") -> 0 | J38: =IFERROR(H38*E38," ") -> 0 | W38: 61308 | X38: ｲﾉｳｴﾉｳｷｼｮｳｶｲ | Y38: ㈲井上農機商会 | Z38: 299-4501 | AA38: 千葉県 いすみ市 岬町椎木1793 | AB38: 0470-87-2823
A39: 税抜小売 | B39: 掛率 | C39: 単価 | D39: OBIC照合 | F39: 伝票NO： | H39: 合計 | J39: =SUM(J33:J36) -> -55900 | W39: 61309 | X39: ｵｵﾏﾁﾉｳｷ | Y39: ㈲大町農機 | Z39: 272-0801 | AA39: 千葉県 市川市 大町453 | AB39: 047-338-1210
A40: =L11 -> 698000 | B40: =T10 -> 0.62 | C40: =F33 -> 432700 | D40: =IFERROR((E33*C40)," ") -> 432700 | F40: 出荷確認 | H40: 受注可否検討 | J40: 連絡書作成 | W40: 61310 | X40: ｲｼﾞﾏｼｮｳﾃﾝ | Y40: ㈲木嶋商店 | Z40: 289-1115 | AA40: 千葉県 八街市 八街ほ377 | AB40: 0434-44-2481
...

Sheet 引合書+値引
A1: （様式：EL-97A03） | V1: 納入先コード | W1: 納入先カナ名 | X1: 納入先正式名 | Y1: 郵便番号1 | Z1: 住所1 | AA1: 電話番号1-1
A2: 引き合い内容連絡書 | J2: 株式会社オーレック | V2: 61102 | W2: ﾆﾎﾝｸﾘﾝﾄﾝ | X2: 日本クリントン㈱ | Y2: 121-0836 | Z2: 東京都 足立区 入谷5-7-8 | AA2: 03-3854-8221
A3: 得意先NO： | B3: 得意先名 及び 担当者名： | I3: 受注日： | V3: 61103 | W3: ﾄｳｺｳｻﾝｷﾞｮｳ | X3: 東興産業㈱ | Y3: 350-0821 | Z3: 埼玉県 川越市 福田239 | AA3: 0492-23-1217
A4: 61376 | C4: =IFERROR(VLOOKUP(A4,請求先!A:D,2,FALSE)," ") -> 有限会社 良栄社商会 | I4: =TODAY() -> 46201 | L4: 製品コード検索 | V4: 61105 | W4: ｲﾄｳｻﾝｷﾞｮｳｷｶｲ | X4: 伊藤産業機械㈱ | Y4: 290-0034 | Z4: 千葉県 市原市 島野1978 | AA4: 0436-22-1743
A5: 納入先NO： | B5: 納入先名及び 担当者名： | G5: 生産日 | H5: 在庫 | I5: 出荷希望日： | L5: RM984X/K | Q5: → | R5: =IFERROR(VLOOKUP(L5,商品コード!B:F,5,FALSE)," ") -> 0352-0110 | V5: 61106 | W5: ｴﾑｴｽｹｰﾉｳｷﾞｮｳｷｶｲﾁﾊﾞｼﾞｷﾞｮｳｼｮ | X5: MSK東急機械㈱ 千葉事業所 | Y5: 290-0012 | Z5: 千葉県 市原市 藤井3-310 | AA5: 0436-41-1069
A6: 61376 | C6: =IFERROR(VLOOKUP(A6,出荷先!A:F,3,FALSE)," ") -> ㈲良栄社商会 | I6: 46196 | V6: 61107 | W6: ｻｻｷｼｮｳｶｲ | X6: ㈱佐々木商会 | Y6: 294-0037 | Z6: 千葉県 館山市 長須賀123 | AA6: 0470-22-1166
B7: 住所： | C7: 〒 | D7: =IFERROR(VLOOKUP(A6,出荷先!A:F,4,FALSE)," ") -> 299-1151 | I7: TEL | L7: 実演機対応値引 | Q7: =IF(Q6="","",VLOOKUP(Q6,#REF!,2,FALSE)) | V7: 61108 | W7: ｽｷﾞｷﾃｯｺｳ | X7: 杉木鉄工㈱ | Y7: 297-0029 | Z7: 千葉県 茂原市 高師1536 | AA7: 0475-22-4587
B8: =IFERROR(VLOOKUP(A6,出荷先!A:F,5,FALSE)," ") -> 千葉県 君津市 中野4-15-18 | I8: =IFERROR(VLOOKUP(A6,出荷先!A:F,6,FALSE)," ") -> 0439-52-0035 | L8: =IF(L7="","",VLOOKUP(L7,商品コード!A:B,2,FALSE)) -> 外掛 | M8: =IF(I8="","",VLOOKUP(I8,商品コード!#REF!,2,FALSE)) -> #REF! | N8: 8 | P8: % | V8: 61109 | W8: ﾀｶﾉｻﾝｷﾞｮｳ | X8: 高野産業㈱ | Y8: 292-0054 | Z8: 千葉県 木更津市 長須賀924-1 | AA8: 0438-22-6251
N9: ] | V9: 61110 | W9: ｶﾝﾄｳｺｼﾝｸﾎﾞﾀﾁﾊﾞｼﾞｷﾞｮｳﾌﾞ | X9: ㈱関東甲信クボタ 南関東事業所 | Y9: 260-0808 | Z9: 千葉県 千葉市 中央区 星久喜町176-4 | AA9: 043-261-3131
A10: 商品番号 | B10: 商品名 | E10: 数量 | F10: 単位 | G10: 単価 | I10: オーダーＮｏ 等 | L10: 税別小売 | N10: 通常 | P10: =IF(A4="","",VLOOKUP(A4,請求先!A:D,4,FALSE)) -> 0.68 | Q10: 値引 | R10: =$N$8/100 -> 0.08 | S10: 最終 | T10: =IF(L8="外掛",P10-R10,IF(L8="内掛",ROUNDDOWN(P10*(100-100*R10)%,5))) -> 0.6 | V10: 61111 | W10: ﾅｶﾔｼｮｳｶｲ | X10: ㈱中屋商会 | Y10: 289-2146 | Z10: 千葉県 匝瑳市 八日市場ホ452 | AA10: 0479-72-1161
A11: 0353-0020 | B11: =IFERROR(VLOOKUP(A11,商品コード!A:C,2,FALSE)," ") -> SP753B/M | E11: 1 | G11: =O13 -> 0 | K11: → | L11: =IF(A11="","",VLOOKUP(A11,商品コード!A:C,3,FALSE)) -> 328000 | N11: =IFERROR(IF(A4=61121,ROUNDDOWN((L11*P10),-1),IF(A4=61123,ROUNDDOWN((L11*P10),-1),IF(A4=64445001,ROUNDDOWN((L11*P10),-1),IF(A4=64445002,ROUNDDOWN((L11*P10),-1),ROUNDDOWN(L11*P10,-2)))))," ") -> 223000 | Q11: =IFERROR(S11-N11," ") -> -26200 | S11: =IFERROR(IF(OR(A4=61121,A4=61123,A4=64445001,A4=64445002),IF(L8="内掛",ROUNDDOWN(N11*(1-R10),-1),ROUNDDOWN(L11*T10,-1)),IF(L8="内掛",ROUNDDOWN(N11*(1-R10),-2),ROUNDDOWN(L11*T10,-2)))," ") -> 196800 | V11: 61112 | W11: ﾅｶﾑﾗｻﾝｷﾞｮｳ | X11: ㈱中村産業 | Y11: 283-0811 | Z11: 千葉県 東金市 台方246 | AA11: 0475-52-2615
B12: =IFERROR(VLOOKUP(A12,商品コード!A:C,2,FALSE)," ") | G12: =O14 -> 0 | K12: → | L12: =IF(A12="","",VLOOKUP(A12,商品コード!A:C,3,FALSE)) | N12: =IFERROR(IF(A4=61121,ROUNDDOWN((L12*P10),-1),IF(A4=61123,ROUNDDOWN((L12*P10),-1),IF(A4=64445001,ROUNDDOWN((L12*P10),-1),IF(A4=64445002,ROUNDDOWN((L12*P10),-1),ROUNDDOWN(L12*P10,-2)))))," ") | Q12: =IFERROR(S12-N12," ") | S12: =IFERROR(IF(OR(A4=61121,A4=61123,A4=64445001,A4=64445002),IF(L8="内掛",ROUNDDOWN(N12*(1-R10),-1),ROUNDDOWN(L12*T10,-1)),IF(L9="内掛",ROUNDDOWN(N12*(1-R10),-2),ROUNDDOWN(L12*T10,-2)))," ") | V12: 61113 | W12: ﾌﾀﾊﾞｺｳｷ | X12: ㈲双葉工機 | Y12: 270-2222 | Z12: 千葉県 松戸市 高塚新田340-11 | AA12: 0473-92-7256
B13: =IFERROR(VLOOKUP(A13,商品コード!A:C,2,FALSE)," ") | G13: =O15 -> 0 | K13: → | L13: =IF(A13="","",VLOOKUP(A13,商品コード!A:C,3,FALSE)) | N13: =IFERROR(IF(A4=61121,ROUNDDOWN((L13*P10),-1),IF(A4=61123,ROUNDDOWN((L13*P10),-1),IF(A4=64445001,ROUNDDOWN((L13*P10),-1),IF(A4=64445002,ROUNDDOWN((L13*P10),-1),ROUNDDOWN(L13*P10,-2)))))," ") | Q13: =IFERROR(S13-N13," ") | S13: =IFERROR(IF(OR(A4=61121,A4=61123,A4=64445001,A4=64445002),IF(L8="内掛",ROUNDDOWN(N13*(1-R10),-1),ROUNDDOWN(L13*T10,-1)),IF(L10="内掛",ROUNDDOWN(N13*(1-R10),-2),ROUNDDOWN(L13*T10,-2)))," ") | V13: 61114 | W13: ﾓﾊﾞﾗﾌｺｸｼｬ | X13: ㈱茂原富国社 | Y13: 297-0029 | Z13: 千葉県 茂原市 高師1671 | AA13: 0475-25-0325
B14: =IFERROR(VLOOKUP(A14,商品コード!A:C,2,FALSE)," ") | G14: =O16 -> 0 | K14: → | L14: =IF(A14="","",VLOOKUP(A14,商品コード!A:C,3,FALSE)) | N14: =IFERROR(IF(A4=61121,ROUNDDOWN((L14*P10),-1),IF(A4=61123,ROUNDDOWN((L14*P10),-1),IF(A4=64445001,ROUNDDOWN((L14*P10),-1),IF(A4=64445002,ROUNDDOWN((L14*P10),-1),ROUNDDOWN(L14*P10,-2)))))," ") | Q14: =IFERROR(S14-N14," ") | S14: =IFERROR(IF(OR(A4=61121,A4=61123,A4=64445001,A4=64445002),IF(L8="内掛",ROUNDDOWN(N14*(1-R10),-1),ROUNDDOWN(L14*T10,-1)),IF(L10="内掛",ROUNDDOWN(N14*(1-R10),-2),ROUNDDOWN(L14*T10,-2)))," ") | V14: 61115 | W14: ｲﾊﾞﾗｷﾘｮｳﾉｳ | X14: 茨城菱農㈱ | Y14: 300-4201 | Z14: 茨城県 つくば市 寺具1332-9 | AA14: 0298-69-1045
B15: =IFERROR(VLOOKUP(A15,商品コード!A:C,2,FALSE)," ") | G15: =O17 -> 0 | L15: 生産日 | N15: 45870 | V15: 61116 | W15: ｶﾝﾄｳｺｳｼﾝｸﾎﾞﾀｲﾊﾞﾗｷｼﾞﾑｼｮ | X15: ㈱関東甲信クボタ 茨城事務所 | Y15: 300-2402 | Z15: 茨城県 つくばみらい市 坂野新田12-42 | AA15: 0297-52-1111
B16: =IFERROR(VLOOKUP(A16,商品コード!A:C,2,FALSE)," ") | G16: =O18 -> 0 | V16: 61117 | W16: ｵｵｶﾜｷｶｲ | X16: 大川機械 | Y16: 300-0024 | Z16: 茨城県 土浦市 田村町988-2 | AA16: 0298-28-0755
A17: 倉庫（ | B17: 031 | C17: ） | D17: 運賃 | E17: 元払い | F17: 伝票NO： | V17: 61118 | W17: ﾐﾂﾋﾞｼﾉｳｷﾊﾝﾊﾞｲｲﾊﾞﾗｷｼﾃﾝ | X17: 三菱農機販売㈱ 茨城支店 | Y17: 311-0133 | Z17: 茨城県 那珂市 鴻巣1135-1 | AA17: 0293-53-2140
E18: 立 元 | F18: 出荷確認 | H18: 受注可否検討 | J18: 連絡書作成 | V18: 61120 | W18: ｼﾏｻﾉｳｷ | X18: ㈱嶋田農機 | Y18: 300-3544 | Z18: 茨城県 結城郡 八千代町 若996 | AA18: 0296-48-1025
E19: 着払い | F19: 承認 | H19: 承認 | J19: 作成者 | V19: 61121 | W19: ｸﾎﾞﾀｲﾊﾞﾗｷｹﾝｴｲｷﾞｮｳﾀﾝﾄｳ | X19: ㈱クボタ 茨城県営業担当 | Y19: 338-0832 | Z19: 埼玉県 さいたま市 桜区 西堀5-2-36 | AA19: 048-862-1125
C20: 便名： | D20: 福山便 西濃便 JPロジ | V20: 61122 | W20: ﾅﾘﾀｶﾄｳﾉｳｷ | X20: 成田加藤農機（有） | Y20: 286-0021 | Z20: 千葉県 成田市 土屋1375-1 | AA20: 0476-22-0579
V21: 61123 | W21: ｸﾎﾞﾀﾄﾁｷﾞｹﾝｴｲｷﾞｮｳﾀﾝﾄｳ | X21: ㈱クボタ 栃木県営業担当 | Y21: 338-0832 | Z21: 埼玉県 さいたま市 桜区 西堀5-2-36 | AA21: 048-862-1125
V22: 61124 | W22: ﾈﾓﾄｼｮｳｶｲ | X22: ㈲根本商会 | Y22: 286-0801 | Z22: 千葉県 成田市 竜台468 | AA22: 0476-37-1211
A23: （様式：EL-97A03） | D23: 【 値引 】 | V23: 61125 | W23: ﾏﾙﾃﾝｻﾝｷﾞｮｳｷｶｲ | X23: マルテン産業機械㈱ | Y23: 293-0001 | Z23: 千葉県 富津市 大堀1434 | AA23: 0439-87-0052
A24: 引き合い内容連絡書 | J24: 株式会社オーレック | V24: 61126 | W24: ﾐﾂﾋﾞｼﾉｳｷﾊﾝﾊﾞｲﾁﾊﾞｼﾃﾝ | X24: 三菱農機販売㈱ 千葉支店 | Y24: 300-1312 | Z24: 茨城県 稲敷郡 河内町 長竿字西の町1596-2 | AA24: 0297-63-4633
A25: 得意先NO： | B25: 得意先名 及び 担当者名： | I25: 受注日： | V25: 61127 | W25: ｸﾎﾞﾀｸﾞﾝﾏｹﾝｴｲｷﾞｮｳﾀﾝﾄｳ | X25: ㈱クボタ 群馬県営業担当 | Y25: 338-0832 | Z25: 埼玉県 さいたま市 桜区 西堀5-2-36 | AA25: 048-862-1125
A26: =A4 -> 61376 | C26: =C4 -> 有限会社 良栄社商会 | I26: =I4 -> 46201 | V26: 61133 | W26: ﾏｷﾀﾇﾏﾂﾞﾋｶﾞｼﾆﾎﾝ | X26: ㈱マキタ沼津 東日本支店 | Y26: 362-0031 | Z26: 埼玉県 上尾市 東町2-8-4 | AA26: 048-779-2262
A27: 納入先NO： | B27: 納入先名及び 担当者名： | I27: 出荷希望日： | V27: 61134 | W27: ｸﾎﾞﾀｹﾝｷｼﾞｬﾊﾟﾝﾁﾊﾞｴｲｷﾞｮｳｼｮ | X27: ㈱クボタ建機ジャパン千葉営業所 | Y27: 283-0823 | Z27: 千葉県 東金市 山田 字新田1201-10 | AA27: 茨城菱農
A28: =A6 -> 61376 | C28: =C6 -> ㈲良栄社商会 | I28: =I6 -> 46196 | V28: 61135 | W28: ｵｵｻﾜｷｶｲ | X28: 大沢機械 | Y28: 191-0043 | Z28: 東京都 日野市 平山6-2-1 | AA28: 042-591-1588
B29: 住所： | I29: TEL | V29: 61136 | W29: ｼﾊﾞﾀ | X29: ㈱シバタ | Y29: 104-0032 | Z29: 東京都 中央区 八丁堀4-3-1 | AA29: 03-3552-0381
V30: 61140 | W30: ﾏｷﾀﾇﾏﾂﾞｷﾞｮｳﾑﾌﾞｼｮｳﾋﾝｶ | X30: ㈱マキタ沼津 業務部商品課 | Y30: 410-0022 | Z30: 静岡県 沼津市 大岡35 | AA30: 055-963-1112
V31: 61301 | W31: ｶﾅｴｻﾝｷﾞｮｳ | X31: カナエ産業㈱ | Y31: 194-0215 | Z31: 東京都 町田市 小山ケ丘3-7-10 | AA31: 042-798-7181
A32: 商品番号 | B32: 商品名 | E32: 数量 | F32: 値引後(仕切) | H32: 単価 | J32: 合計 | V32: 61302 | W32: ﾖｼｻﾞﾜｹﾞﾝﾄﾞｳｷ | X32: 吉澤原動機 | Y32: 114-0013 | Z32: 東京都 北区 東田端2-8-6 | AA32: 03-3810-2700
A33: =A11 -> 0353-0020 | B33: =B11 -> SP753B/M | E33: =E11 -> 1 | F33: =S11 -> 196800 | H33: =IFERROR(Q11," ") -> -26200 | J33: =IFERROR(H33*E33," ") -> -26200 | V33: 61303 | W33: ﾐﾔｼﾞｷｶｲ | X33: ㈱宮地機械（出荷停止） | Y33: 177-0033 | Z33: 東京都 練馬区 高野台4-11-28 | AA33: 03-3997-3155
A34: =A12 -> 0 | B34: =B12 | E34: =E12 -> 0 | F34: =S12 | H34: =IFERROR(Q12," ") | J34: =IFERROR(H34*E34," ") | V34: 61304 | W34: ﾊﾁｷﾞｮｳｼｮｳｼﾞ | X34: 八丈商事 | Y34: 100-1401 | Z34: 東京都 八丈島 八丈町 大賀郷1098-2 | AA34: 04996-2-2189
A35: =A13 -> 0 | E35: =E13 -> 0 | F35: =S13 | H35: =IFERROR(Q13," ") | J35: =IFERROR(H35*E35," ") | V35: 61305 | W35: ｲｼｲﾃﾞﾝｷｼｮｳﾃﾝ | X35: ㈱石井電気商店 | Y35: 294-0042 | Z35: 千葉県 館山市 上野原294-5 | AA35: 0470-22-0542
A36: =A14 -> 0 | B36: =B14 | E36: =E14 -> 0 | F36: =S14 | H36: =IFERROR(Q14," ") | J36: =IFERROR(H36*E36," ") | V36: 61306 | W36: ｲｺﾞｳﾉｳｷ | X36: ㈲井合農機店 | Y36: 273-0047 | Z36: 千葉県 船橋市 藤原5-22-31 | AA36: 047-439-5477
A37: =A15 -> 0 | B37: =B15 | E37: =E15 -> 0 | F37: =S15 -> 0 | H37: =IFERROR(-(S17)," ") -> 0 | J37: =IFERROR(H37*E37," ") -> 0 | V37: 61307 | W37: ｲｼｲﾃｯｺｳ | X37: 石井鉄工㈱ | Y37: 299-4218 | Z37: 千葉県 長生郡 白子町 関4549-2 | AA37: 0475-33-3528
A38: =A16 -> 0 | B38: =B16 | E38: =E16 -> 0 | F38: =Q18 -> 0 | H38: =IFERROR(-(S18)," ") -> 0 | J38: =IFERROR(H38*E38," ") -> 0 | V38: 61308 | W38: ｲﾉｳｴﾉｳｷｼｮｳｶｲ | X38: ㈲井上農機商会 | Y38: 299-4501 | Z38: 千葉県 いすみ市 岬町椎木1793 | AA38: 0470-87-2823
A39: 税抜小売 | B39: 掛率 | C39: 単価 | D39: OBIC照合 | F39: 伝票NO： | H39: 合計 | J39: =SUM(J33:J36) -> -26200 | V39: 61309 | W39: ｵｵﾏﾁﾉｳｷ | X39: ㈲大町農機 | Y39: 272-0801 | Z39: 千葉県 市川市 大町453 | AA39: 047-338-1210
A40: =L11 -> 328000 | B40: =T10 -> 0.6 | C40: =F33 -> 196800 | D40: =IFERROR((E33*C40)," ") -> 196800 | F40: 出荷確認 | H40: 受注可否検討 | J40: 連絡書作成 | V40: 61310 | W40: ｲｼﾞﾏｼｮｳﾃﾝ | X40: ㈲木嶋商店 | Y40: 289-1115 | Z40: 千葉県 八街市 八街ほ377 | AA40: 0434-44-2481
...

Sheet 三菱+値引
A1: （様式：EL-97A03） | Y1: 納入先コード | Z1: 納入先カナ名 | AA1: 納入先正式名 | AB1: 郵便番号1 | AC1: 住所1 | AD1: 電話番号1-1
A2: 引き合い内容連絡書 | J2: 株式会社オーレック | Y2: 61102 | Z2: ﾆﾎﾝｸﾘﾝﾄﾝ | AA2: 日本クリントン㈱ | AB2: 121-0836 | AC2: 東京都 足立区 入谷5-7-8 | AD2: 03-3854-8221
A3: 得意先NO： | B3: 得意先名 及び 担当者名： | I3: 受注日： | Y3: 61103 | Z3: ﾄｳｺｳｻﾝｷﾞｮｳ | AA3: 東興産業㈱ | AB3: 350-0821 | AC3: 埼玉県 川越市 福田239 | AD3: 0492-23-1217
A4: 64445005 | C4: =IFERROR(VLOOKUP(A4,請求先!A:D,2,FALSE)," ") -> 三菱マヒンドラ農機㈱（千葉県） | I4: 46080 | L4: 製品コード検索 | Y4: 61105 | Z4: ｲﾄｳｻﾝｷﾞｮｳｷｶｲ | AA4: 伊藤産業機械㈱ | AB4: 290-0034 | AC4: 千葉県 市原市 島野1978 | AD4: 0436-22-1743
A5: 納入先NO： | B5: 納入先名及び 担当者名： | G5: 生産日 | H5: 在庫分 | I5: 出荷希望日： | L5: SP853/Y | Q5: → | R5: =IFERROR(VLOOKUP(L5,商品コード!B:F,5,FALSE)," ") | Y5: 61106 | Z5: ｴﾑｴｽｹｰﾉｳｷﾞｮｳｷｶｲﾁﾊﾞｼﾞｷﾞｮｳｼｮ | AA5: MSK東急機械㈱ 千葉事業所 | AB5: 290-0012 | AC5: 千葉県 市原市 藤井3-310 | AD5: 0436-41-1069
A6: 2135542 | C6: =IFERROR(VLOOKUP(A6,出荷先!A:F,3,FALSE)," ") -> JAちばみどり 農機センター | I6: 46084 | Y6: 61107 | Z6: ｻｻｷｼｮｳｶｲ | AA6: ㈱佐々木商会 | AB6: 294-0037 | AC6: 千葉県 館山市 長須賀123 | AD6: 0470-22-1166
B7: 住所： | C7: 〒 | D7: =IFERROR(VLOOKUP(A6,出荷先!A:F,4,FALSE)," ") -> 289-2503 | L7: 実演機対応値引 | Q7: =IF(Q6="","",VLOOKUP(Q6,#REF!,2,FALSE)) | S7: M-TOS 報告 | Y7: 61108 | Z7: ｽｷﾞｷﾃｯｺｳ | AA7: 杉木鉄工㈱ | AB7: 297-0029 | AC7: 千葉県 茂原市 高師1536 | AD7: 0475-22-4587
B8: =IFERROR(VLOOKUP(A6,出荷先!A:F,5,FALSE)," ") -> 千葉県 旭市 江ヶ崎661 | I8: =IFERROR(VLOOKUP(A6,出荷先!A:F,6,FALSE)," ") -> 0479-63-7009 | L8: =IF(L7="","",VLOOKUP(L7,商品コード!A:B,2,FALSE)) -> 外掛 | M8: =IF(I8="","",VLOOKUP(I8,商品コード!#REF!,2,FALSE)) -> #REF! | N8: 2 | P8: % | S8: 三菱マヒンドラ | U8: 三菱販社 | Y8: 61109 | Z8: ﾀｶﾉｻﾝｷﾞｮｳ | AA8: 高野産業㈱ | AB8: 292-0054 | AC8: 千葉県 木更津市 長須賀924-1 | AD8: 0438-22-6251
Y9: 61110 | Z9: ｶﾝﾄｳｺｼﾝｸﾎﾞﾀﾁﾊﾞｼﾞｷﾞｮｳﾌﾞ | AA9: ㈱関東甲信クボタ 南関東事業所 | AB9: 260-0808 | AC9: 千葉県 千葉市 中央区 星久喜町176-4 | AD9: 043-261-3131
A10: 商品番号 | B10: 商品名 | E10: 数量 | F10: 単位 | G10: 単価 | I10: オーダーＮｏ 等 | L10: 税別小売 | N10: 通常 | P10: =IF(A4="","",VLOOKUP(A4,請求先!A:D,4,FALSE)) -> 0.637 | Q10: 値引 | R10: =$N$8/100 -> 0.02 | S10: 最終 | T10: =IF(L8="外掛",P10-R10,IF(L8="内掛",ROUNDDOWN(P10*(100-100*R10)%,5))) -> 0.617 | U10: =IF(L8="外掛",(65-N8)%,IF(L8="内掛",(65*(1-N8/100))%)) -> 0.63 | Y10: 61111 | Z10: ﾅｶﾔｼｮｳｶｲ | AA10: ㈱中屋商会 | AB10: 289-2146 | AC10: 千葉県 匝瑳市 八日市場ホ452 | AD10: 0479-72-1161
A11: 0353-0260 | B11: =IFERROR(VLOOKUP(A11,商品コード!A:C,2,FALSE)," ") -> SP853A/Y | E11: 1 | G11: =O13 -> 0 | I11: A44208 | K11: → | L11: =IF(A11="","",VLOOKUP(A11,商品コード!A:C,3,FALSE)) -> 308000 | N11: =IFERROR(IF(A4=61121,ROUNDDOWN((L11*P10),-1),IF(A4=61123,ROUNDDOWN((L11*P10),-1),IF(A4=64445001,ROUNDDOWN((L11*P10),-1),IF(A4=64445002,ROUNDDOWN((L11*P10),-1),ROUNDDOWN(L11*P10,-1)))))," ") -> 196190 | Q11: =IFERROR(S11-N11," ") -> -6070 | S11: =IFERROR(ROUNDDOWN(U11*0.98,-1)," ") -> 190120 | U11: =IFERROR(IF(L8="外掛",ROUNDDOWN(L11*((65-N8)/100),-2),IF(L8="内掛",ROUNDDOWN(ROUNDDOWN(L11*0.65,-2)*(1-N8/100),-2)))," ") -> 194000 | Y11: 61112 | Z11: ﾅｶﾑﾗｻﾝｷﾞｮｳ | AA11: ㈱中村産業 | AB11: 283-0811 | AC11: 千葉県 東金市 台方246 | AD11: 0475-52-2615
G12: =O14 -> 0 | K12: → | L12: =IF(A12="","",VLOOKUP(A12,商品コード!A:C,3,FALSE)) | N12: =IFERROR(IF(A4=61121,ROUNDDOWN((L12*P10),-1),IF(A4=61123,ROUNDDOWN((L12*P10),-1),IF(A4=64445001,ROUNDDOWN((L12*P10),-1),IF(A4=64445002,ROUNDDOWN((L12*P10),-1),ROUNDDOWN(L12*P10,-2)))))," ") | Q12: =IFERROR(S12-N12," ") | S12: =IFERROR(ROUNDDOWN(U12*0.98,-1)," ") | U12: =IFERROR(IF(L8="外掛",ROUNDDOWN(L12*((65-N8)/100),-2),IF(L8="内掛",ROUNDDOWN(ROUNDDOWN(L12*0.65,-2)*(1-N8/100),-2)))," ") | Y12: 61113 | Z12: ﾌﾀﾊﾞｺｳｷ | AA12: ㈲双葉工機 | AB12: 270-2222 | AC12: 千葉県 松戸市 高塚新田340-11 | AD12: 0473-92-7256
B13: =IFERROR(VLOOKUP(A13,商品コード!A:C,2,FALSE)," ") | G13: =O15 -> 0 | K13: → | L13: =IF(A13="","",VLOOKUP(A13,商品コード!A:C,3,FALSE)) | N13: =IFERROR(IF(A4=61121,ROUNDDOWN((L13*P10),-1),IF(A4=61123,ROUNDDOWN((L13*P10),-1),IF(A4=64445001,ROUNDDOWN((L13*P10),-1),IF(A4=64445002,ROUNDDOWN((L13*P10),-1),ROUNDDOWN(L13*P10,-2)))))," ") | Q13: =IFERROR(S13-N13," ") | S13: =IFERROR(ROUNDDOWN(U13*0.98,-1)," ") | U13: =IFERROR(IF(L8="外掛",ROUNDDOWN(L13*((65-N8)/100),-2),IF(L8="内掛",ROUNDDOWN(ROUNDDOWN(L13*0.65,-2)*(1-N8/100),-2)))," ") | Y13: 61114 | Z13: ﾓﾊﾞﾗﾌｺｸｼｬ | AA13: ㈱茂原富国社 | AB13: 297-0029 | AC13: 千葉県 茂原市 高師1671 | AD13: 0475-25-0325
B14: =IFERROR(VLOOKUP(A14,商品コード!A:C,2,FALSE)," ") | G14: =O16 -> 0 | K14: → | L14: =IF(A14="","",VLOOKUP(A14,商品コード!A:C,3,FALSE)) | N14: =IFERROR(IF(A4=61121,ROUNDDOWN((L14*P10),-1),IF(A4=61123,ROUNDDOWN((L14*P10),-1),IF(A4=64445001,ROUNDDOWN((L14*P10),-1),IF(A4=64445002,ROUNDDOWN((L14*P10),-1),ROUNDDOWN(L14*P10,-2)))))," ") | Q14: =IFERROR(S14-N14," ") | S14: =IFERROR(ROUNDDOWN(U14*0.98,-1)," ") | U14: =IFERROR(IF(L8="外掛",ROUNDDOWN(L14*((65-N8)/100),-2),IF(L8="内掛",ROUNDDOWN(ROUNDDOWN(L14*0.65,-2)*(1-N8/100),-2)))," ") | Y14: 61115 | Z14: ｲﾊﾞﾗｷﾘｮｳﾉｳ | AA14: 茨城菱農㈱ | AB14: 300-4201 | AC14: 茨城県 つくば市 寺具1332-9 | AD14: 0298-69-1045
B15: =IFERROR(VLOOKUP(A15,商品コード!A:C,2,FALSE)," ") | G15: =O17 -> 0 | Y15: 61116 | Z15: ｶﾝﾄｳｺｳｼﾝｸﾎﾞﾀｲﾊﾞﾗｷｼﾞﾑｼｮ | AA15: ㈱関東甲信クボタ 茨城事務所 | AB15: 300-2402 | AC15: 茨城県 つくばみらい市 坂野新田12-42 | AD15: 0297-52-1111
B16: =IFERROR(VLOOKUP(A16,商品コード!A:C,2,FALSE)," ") | G16: =O18 -> 0 | Y16: 61117 | Z16: ｵｵｶﾜｷｶｲ | AA16: 大川機械 | AB16: 300-0024 | AC16: 茨城県 土浦市 田村町988-2 | AD16: 0298-28-0755
A17: 倉庫（ | B17: 033 | C17: ） | D17: 運賃 | E17: 元払い | F17: 伝票NO： | Y17: 61118 | Z17: ﾐﾂﾋﾞｼﾉｳｷﾊﾝﾊﾞｲｲﾊﾞﾗｷｼﾃﾝ | AA17: 三菱農機販売㈱ 茨城支店 | AB17: 311-0133 | AC17: 茨城県 那珂市 鴻巣1135-1 | AD17: 0293-53-2140
E18: 立 元 | F18: 出荷確認 | H18: 受注可否検討 | J18: 連絡書作成 | Y18: 61120 | Z18: ｼﾏｻﾉｳｷ | AA18: ㈱嶋田農機 | AB18: 300-3544 | AC18: 茨城県 結城郡 八千代町 若996 | AD18: 0296-48-1025
E19: 着払い | F19: 承認 | H19: 承認 | J19: 作成者 | Y19: 61121 | Z19: ｸﾎﾞﾀｲﾊﾞﾗｷｹﾝｴｲｷﾞｮｳﾀﾝﾄｳ | AA19: ㈱クボタ 茨城県営業担当 | AB19: 338-0832 | AC19: 埼玉県 さいたま市 桜区 西堀5-2-36 | AD19: 048-862-1125
C20: 便名： | D20: 福山便 西濃便 JPロジ | Y20: 61122 | Z20: ﾅﾘﾀｶﾄｳﾉｳｷ | AA20: 成田加藤農機（有） | AB20: 286-0021 | AC20: 千葉県 成田市 土屋1375-1 | AD20: 0476-22-0579
Y21: 61123 | Z21: ｸﾎﾞﾀﾄﾁｷﾞｹﾝｴｲｷﾞｮｳﾀﾝﾄｳ | AA21: ㈱クボタ 栃木県営業担当 | AB21: 338-0832 | AC21: 埼玉県 さいたま市 桜区 西堀5-2-36 | AD21: 048-862-1125
Y22: 61124 | Z22: ﾈﾓﾄｼｮｳｶｲ | AA22: ㈲根本商会 | AB22: 286-0801 | AC22: 千葉県 成田市 竜台468 | AD22: 0476-37-1211
A23: （様式：EL-97A03） | D23: 【 値引 】 | Y23: 61125 | Z23: ﾏﾙﾃﾝｻﾝｷﾞｮｳｷｶｲ | AA23: マルテン産業機械㈱ | AB23: 293-0001 | AC23: 千葉県 富津市 大堀1434 | AD23: 0439-87-0052
A24: 引き合い内容連絡書 | J24: 株式会社オーレック | Y24: 61126 | Z24: ﾐﾂﾋﾞｼﾉｳｷﾊﾝﾊﾞｲﾁﾊﾞｼﾃﾝ | AA24: 三菱農機販売㈱ 千葉支店 | AB24: 300-1312 | AC24: 茨城県 稲敷郡 河内町 長竿字西の町1596-2 | AD24: 0297-63-4633
A25: 得意先NO： | B25: 得意先名 及び 担当者名： | I25: 受注日： | Y25: 61127 | Z25: ｸﾎﾞﾀｸﾞﾝﾏｹﾝｴｲｷﾞｮｳﾀﾝﾄｳ | AA25: ㈱クボタ 群馬県営業担当 | AB25: 338-0832 | AC25: 埼玉県 さいたま市 桜区 西堀5-2-36 | AD25: 048-862-1125
A26: =A4 -> 64445005 | C26: =C4 -> 三菱マヒンドラ農機㈱（千葉県） | I26: =I4 -> 46080 | Y26: 61133 | Z26: ﾏｷﾀﾇﾏﾂﾞﾋｶﾞｼﾆﾎﾝ | AA26: ㈱マキタ沼津 東日本支店 | AB26: 362-0031 | AC26: 埼玉県 上尾市 東町2-8-4 | AD26: 048-779-2262
A27: 納入先NO： | B27: 納入先名及び 担当者名： | I27: 出荷希望日： | Y27: 61134 | Z27: ｸﾎﾞﾀｹﾝｷｼﾞｬﾊﾟﾝﾁﾊﾞｴｲｷﾞｮｳｼｮ | AA27: ㈱クボタ建機ジャパン千葉営業所 | AB27: 283-0823 | AC27: 千葉県 東金市 山田 字新田1201-10 | AD27: 茨城菱農
A28: =A6 -> 2135542 | C28: =C6 -> JAちばみどり 農機センター | I28: =I6 -> 46084 | Y28: 61135 | Z28: ｵｵｻﾜｷｶｲ | AA28: 大沢機械 | AB28: 191-0043 | AC28: 東京都 日野市 平山6-2-1 | AD28: 042-591-1588
B29: 住所： | I29: TEL | Y29: 61136 | Z29: ｼﾊﾞﾀ | AA29: ㈱シバタ | AB29: 104-0032 | AC29: 東京都 中央区 八丁堀4-3-1 | AD29: 03-3552-0381
Y30: 61140 | Z30: ﾏｷﾀﾇﾏﾂﾞｷﾞｮｳﾑﾌﾞｼｮｳﾋﾝｶ | AA30: ㈱マキタ沼津 業務部商品課 | AB30: 410-0022 | AC30: 静岡県 沼津市 大岡35 | AD30: 055-963-1112
Y31: 61301 | Z31: ｶﾅｴｻﾝｷﾞｮｳ | AA31: カナエ産業㈱ | AB31: 194-0215 | AC31: 東京都 町田市 小山ケ丘3-7-10 | AD31: 042-798-7181
A32: 商品番号 | B32: 商品名 | E32: 数量 | F32: 値引後(仕切) | H32: 単価 | J32: 合計 | Y32: 61302 | Z32: ﾖｼｻﾞﾜｹﾞﾝﾄﾞｳｷ | AA32: 吉澤原動機 | AB32: 114-0013 | AC32: 東京都 北区 東田端2-8-6 | AD32: 03-3810-2700
A33: =A11 -> 0353-0260 | B33: =B11 -> SP853A/Y | E33: =E11 -> 1 | F33: =S11 -> 190120 | H33: =IFERROR(Q11," ") -> -6070 | J33: =IFERROR(H33*E33," ") -> -6070 | Y33: 61303 | Z33: ﾐﾔｼﾞｷｶｲ | AA33: ㈱宮地機械（出荷停止） | AB33: 177-0033 | AC33: 東京都 練馬区 高野台4-11-28 | AD33: 03-3997-3155
A34: =A12 -> 0 | B34: =B12 -> 0 | E34: =E12 -> 0 | F34: =S12 | H34: =IFERROR(Q12," ") | J34: =IFERROR(H34*E34," ") | Y34: 61304 | Z34: ﾊﾁｷﾞｮｳｼｮｳｼﾞ | AA34: 八丈商事 | AB34: 100-1401 | AC34: 東京都 八丈島 八丈町 大賀郷1098-2 | AD34: 04996-2-2189
A35: =A13 -> 0 | B35: =B13 | E35: =E13 -> 0 | F35: =S13 | H35: =IFERROR(Q13," ") | J35: =IFERROR(H35*E35," ") | Y35: 61305 | Z35: ｲｼｲﾃﾞﾝｷｼｮｳﾃﾝ | AA35: ㈱石井電気商店 | AB35: 294-0042 | AC35: 千葉県 館山市 上野原294-5 | AD35: 0470-22-0542
A36: =A14 -> 0 | B36: =B14 | E36: =E14 -> 0 | F36: =S14 | H36: =IFERROR(Q14," ") | J36: =IFERROR(H36*E36," ") | Y36: 61306 | Z36: ｲｺﾞｳﾉｳｷ | AA36: ㈲井合農機店 | AB36: 273-0047 | AC36: 千葉県 船橋市 藤原5-22-31 | AD36: 047-439-5477
A37: =A15 -> 0 | B37: =B15 | E37: =E15 -> 0 | F37: =S15 -> 0 | H37: =IFERROR(-(S17)," ") -> 0 | J37: =IFERROR(H37*E37," ") -> 0 | Y37: 61307 | Z37: ｲｼｲﾃｯｺｳ | AA37: 石井鉄工㈱ | AB37: 299-4218 | AC37: 千葉県 長生郡 白子町 関4549-2 | AD37: 0475-33-3528
A38: =A16 -> 0 | B38: =B16 | E38: =E16 -> 0 | F38: =Q18 -> 0 | H38: =IFERROR(-(S18)," ") -> 0 | J38: =IFERROR(H38*E38," ") -> 0 | Y38: 61308 | Z38: ｲﾉｳｴﾉｳｷｼｮｳｶｲ | AA38: ㈲井上農機商会 | AB38: 299-4501 | AC38: 千葉県 いすみ市 岬町椎木1793 | AD38: 0470-87-2823
A39: 定価 | B39: 掛率 | C39: 単価 | D39: OBIC照合 | E39: 三菱マ/販 | F39: 伝票NO： | H39: 合計 | J39: =SUM(J33:J36) -> -6070 | Y39: 61309 | Z39: ｵｵﾏﾁﾉｳｷ | AA39: ㈲大町農機 | AB39: 272-0801 | AC39: 千葉県 市川市 大町453 | AD39: 047-338-1210
A40: =L11 -> 308000 | B40: =T10 -> 0.617 | C40: =F33 -> 190120 | D40: =IFERROR((E33*C40)," ") -> 190120 | E40: =S11 -> 190120 | F40: 出荷確認 | H40: 受注可否検討 | J40: 連絡書作成 | Y40: 61310 | Z40: ｲｼﾞﾏｼｮｳﾃﾝ | AA40: ㈲木嶋商店 | AB40: 289-1115 | AC40: 千葉県 八街市 八街ほ377 | AD40: 0434-44-2481
...

Sheet 三菱
A1: （様式：EL-97A03）
A2: 引き合い内容連絡書 | J2: 株式会社オーレック
A3: 得意先NO： | B3: 得意先名 及び 担当者名： | I3: 受注日：
A4: 64445005 | C4: =IFERROR(VLOOKUP(A4,請求先!A:D,2,FALSE)," ") -> 三菱マヒンドラ農機㈱（千葉県） | I4: 45996
A5: 納入先NO： | B5: 納入先名及び 担当者名： | G5: 生産日 | H5: 46007 | I5: 出荷希望日：
A6: 69012116 | C6: =IFERROR(VLOOKUP(A6,出荷先!A:F,3,FALSE)," ") -> 平和機械㈱ | I6: 46009
B7: 住所： | C7: 〒 | D7: =IFERROR(VLOOKUP(A6,出荷先!A:F,4,FALSE)," ") -> 299-3266 | I7: TEL
B8: =IFERROR(VLOOKUP(A6,出荷先!A:F,5,FALSE)," ") -> 千葉県 大網白里市 北横川115-4 | I8: =IFERROR(VLOOKUP(A6,出荷先!A:F,6,FALSE)," ") -> 0475-72-0345
A10: 商品番号 | B10: 商品名 | E10: 数量 | F10: 単位 | G10: 単価 | I10: オーダーＮｏ 等
A11: 0353-0260 | B11: =IFERROR(VLOOKUP(A11,商品コード!A:C,2,FALSE)," ") -> SP853A/Y | E11: 1
B12: =IFERROR(VLOOKUP(A12,商品コード!A:C,2,FALSE)," ")
B13: =IFERROR(VLOOKUP(A13,商品コード!A:C,2,FALSE)," ")
B14: =IFERROR(VLOOKUP(A14,商品コード!A:C,2,FALSE)," ")
B15: =IFERROR(VLOOKUP(A15,商品コード!A:C,2,FALSE)," ")
B16: =IFERROR(VLOOKUP(A16,商品コード!A:C,2,FALSE)," ")
A17: 倉庫（ | B17: 011 | C17: ） | D17: 運賃 | E17: 元払い | F17: 伝票NO：
E18: 立 元 | F18: 出荷確認 | H18: 受注可否検討 | J18: 連絡書作成
E19: 着払い | F19: 承認 | H19: 承認 | J19: 作成者
C20: 便名： | D20: 福山便 西濃便 JPロジ
A23: 製品コード検索
A24: HR665/M | F24: → | G24: =IFERROR(VLOOKUP(A24,商品コード!B:F,5,FALSE)," ") -> 0285-0520
A26: M-TOS 報告 | F26: 0.637 | I26: 0.65
A27: 製品型式 | C27: 税別小売 | F27: 三菱マヒンドラ | I27: 三菱販社
A28: =B11 -> SP853A/Y | C28: =IF(A11="","",VLOOKUP(A11,商品コード!$A:$C,3,FALSE)) -> 308000 | F28: =IFERROR(ROUNDDOWN((C28*0.637),-1)," ") -> 196190 | I28: =IFERROR(ROUNDDOWN((C28*0.65),-2)," ") -> 200200
A29: =B12 | C29: =IF(A12="","",VLOOKUP(A12,商品コード!$A:$C,3,FALSE)) | F29: =IFERROR(ROUNDDOWN((C29*0.637),-1)," ") | I29: =IFERROR(ROUNDDOWN((C29*0.65),-2)," ")
A30: =B13 | C30: =IF(A13="","",VLOOKUP(A13,商品コード!$A:$C,3,FALSE)) | F30: =IFERROR(ROUNDDOWN((C30*0.637),-1)," ") | I30: =IFERROR(ROUNDDOWN((C30*0.65),-2)," ")
A31: =B14 | C31: =IF(A14="","",VLOOKUP(A14,商品コード!$A:$C,3,FALSE)) | F31: =IFERROR(ROUNDDOWN((C31*0.637),-1)," ") | I31: =IFERROR(ROUNDDOWN((C31*0.65),-2)," ")
A32: =B15 | C32: =IF(A15="","",VLOOKUP(A15,商品コード!$A:$C,3,FALSE)) | F32: =IFERROR(ROUNDDOWN((C32*0.637),-1)," ") | I32: =IFERROR(ROUNDDOWN((C32*0.65),-2)," ")
A33: =B16 | C33: =IF(A16="","",VLOOKUP(A16,商品コード!$A:$C,3,FALSE)) | F33: =IFERROR(ROUNDDOWN((C33*0.637),-1)," ") | I33: =IFERROR(ROUNDDOWN((C33*0.65),-2)," ")

Sheet 商組不需要期
A1: （様式：EL-97A03） | AA1: 納入先コード | AB1: 納入先カナ名 | AC1: 納入先正式名 | AD1: 郵便番号1 | AE1: 住所1 | AF1: 電話番号1-1
A2: 引き合い内容連絡書 | J2: 株式会社オーレック | AA2: 61102 | AB2: ﾆﾎﾝｸﾘﾝﾄﾝ | AC2: 日本クリントン㈱ | AD2: 121-0836 | AE2: 東京都 足立区 入谷5-7-8 | AF2: 03-3854-8221
A3: 得意先NO： | B3: 得意先名 及び 担当者名： | I3: 受注日： | AA3: 61103 | AB3: ﾄｳｺｳｻﾝｷﾞｮｳ | AC3: 東興産業㈱ | AD3: 350-0821 | AE3: 埼玉県 川越市 福田239 | AF3: 0492-23-1217
C4: =IFERROR(VLOOKUP(A4,請求先!A:D,2,FALSE)," ") | I4: 45957 | L4: 製品コード検索 | AA4: 61105 | AB4: ｲﾄｳｻﾝｷﾞｮｳｷｶｲ | AC4: 伊藤産業機械㈱ | AD4: 290-0034 | AE4: 千葉県 市原市 島野1978 | AF4: 0436-22-1743
A5: 納入先NO： | B5: 納入先名及び 担当者名： | G5: 生産日 | H5: 2月 | I5: 出荷希望日： | L5: SP853/Y | Q5: → | R5: =IFERROR(VLOOKUP(L5,商品コード!B:F,5,FALSE)," ") | AA5: 61106 | AB5: ｴﾑｴｽｹｰﾉｳｷﾞｮｳｷｶｲﾁﾊﾞｼﾞｷﾞｮｳｼｮ | AC5: MSK東急機械㈱ 千葉事業所 | AD5: 290-0012 | AE5: 千葉県 市原市 藤井3-310 | AF5: 0436-41-1069
A6: 61344 | C6: =IFERROR(VLOOKUP(A6,出荷先!A:F,3,FALSE)," ") -> ㈲土子機械店 | I6: 45986 | AA6: 61107 | AB6: ｻｻｷｼｮｳｶｲ | AC6: ㈱佐々木商会 | AD6: 294-0037 | AE6: 千葉県 館山市 長須賀123 | AF6: 0470-22-1166
B7: 住所： | C7: 〒 | D7: =IFERROR(VLOOKUP(A6,出荷先!A:F,4,FALSE)," ") -> 287-0037 | L7: 不需要期値引 | Q7: =IF(Q6="","",VLOOKUP(Q6,#REF!,2,FALSE)) | AA7: 61108 | AB7: ｽｷﾞｷﾃｯｺｳ | AC7: 杉木鉄工㈱ | AD7: 297-0029 | AE7: 千葉県 茂原市 高師1536 | AF7: 0475-22-4587
B8: =IFERROR(VLOOKUP(A6,出荷先!A:F,5,FALSE)," ") -> 千葉県 香取市 与倉73-4 | I8: =IFERROR(VLOOKUP(A6,出荷先!A:F,6,FALSE)," ") -> 0478-58-1134 | L8: =IF(L7="","",VLOOKUP(L7,商品コード!A:B,2,FALSE)) -> 内掛 | M8: =IF(I8="","",VLOOKUP(I8,商品コード!#REF!,2,FALSE)) -> #REF! | N8: 5 | P8: % | AA8: 61109 | AB8: ﾀｶﾉｻﾝｷﾞｮｳ | AC8: 高野産業㈱ | AD8: 292-0054 | AE8: 千葉県 木更津市 長須賀924-1 | AF8: 0438-22-6251
AA9: 61110 | AB9: ｶﾝﾄｳｺｼﾝｸﾎﾞﾀﾁﾊﾞｼﾞｷﾞｮｳﾌﾞ | AC9: ㈱関東甲信クボタ 南関東事業所 | AD9: 260-0808 | AE9: 千葉県 千葉市 中央区 星久喜町176-4 | AF9: 043-261-3131
A10: 商品番号 | B10: 商品名 | E10: 数量 | F10: 単位 | G10: 単価 | I10: オーダーＮｏ 等 | L10: 税別小売 | N10: 通常 | P10: =IF(A4="","",VLOOKUP(A4,請求先!A:D,4,FALSE)) | Q10: 値引 | R10: =$N$8/100 -> 0.05 | S10: 最終 | T10: =IF(L8="外掛",P10-R10,IF(L8="内掛",ROUNDDOWN(P10*(100-100*R10)%,5))) -> #VALUE! | AA10: 61111 | AB10: ﾅｶﾔｼｮｳｶｲ | AC10: ㈱中屋商会 | AD10: 289-2146 | AE10: 千葉県 匝瑳市 八日市場ホ452 | AF10: 0479-72-1161
A11: 0353-0260 | B11: =IFERROR(VLOOKUP(A11,商品コード!A:C,2,FALSE)," ") -> SP853A/Y | E11: 1 | G11: =O13 -> 0 | K11: → | L11: =IF(A11="","",VLOOKUP(A11,商品コード!A:C,3,FALSE)) -> 308000 | N11: =IFERROR(IF(A4=61121,ROUNDDOWN((L11*P10),-1),IF(A4=61123,ROUNDDOWN((L11*P10),-1),IF(A4=64445001,ROUNDDOWN((L11*P10),-1),IF(A4=64445002,ROUNDDOWN((L11*P10),-1),ROUNDDOWN(L11*P10,-2)))))," ") | Q11: =IFERROR(S11-N11," ") | S11: =IFERROR(IF(OR(A4=61121,A4=61123,A4=64445001,A4=64445002),IF(L8="内掛",ROUNDDOWN(N11*(1-R10),-1),ROUNDDOWN(L11*T10,-1)),IF(L8="内掛",ROUNDDOWN(N11*(1-R10),-2),ROUNDDOWN(L11*T10,-2)))," ") | AA11: 61112 | AB11: ﾅｶﾑﾗｻﾝｷﾞｮｳ | AC11: ㈱中村産業 | AD11: 283-0811 | AE11: 千葉県 東金市 台方246 | AF11: 0475-52-2615
B12: =IFERROR(VLOOKUP(A12,商品コード!A:C,2,FALSE)," ") | G12: =O14 -> 0 | K12: → | L12: =IF(A12="","",VLOOKUP(A12,商品コード!A:C,3,FALSE)) | N12: =IFERROR(IF(A4=61121,ROUNDDOWN((L12*P10),-1),IF(A4=61123,ROUNDDOWN((L12*P10),-1),IF(A4=64445001,ROUNDDOWN((L12*P10),-1),IF(A4=64445002,ROUNDDOWN((L12*P10),-1),ROUNDDOWN(L12*P10,-2)))))," ") | Q12: =IFERROR(S12-N12," ") | S12: =IFERROR(IF(OR(A4=61121,A4=61123,A4=64445001,A4=64445002),IF(L8="内掛",ROUNDDOWN(N12*(1-R10),-1),ROUNDDOWN(L12*T10,-1)),IF(L8="内掛",ROUNDDOWN(N12*(1-R10),-2),ROUNDDOWN(L12*T10,-2)))," ") | AA12: 61113 | AB12: ﾌﾀﾊﾞｺｳｷ | AC12: ㈲双葉工機 | AD12: 270-2222 | AE12: 千葉県 松戸市 高塚新田340-11 | AF12: 0473-92-7256
B13: =IFERROR(VLOOKUP(A13,商品コード!A:C,2,FALSE)," ") | G13: =O15 -> 0 | K13: → | L13: =IF(A13="","",VLOOKUP(A13,商品コード!A:C,3,FALSE)) | N13: =IFERROR(IF(A4=61121,ROUNDDOWN((L13*P10),-1),IF(A4=61123,ROUNDDOWN((L13*P10),-1),IF(A4=64445001,ROUNDDOWN((L13*P10),-1),IF(A4=64445002,ROUNDDOWN((L13*P10),-1),ROUNDDOWN(L13*P10,-2)))))," ") | Q13: =IFERROR(S13-N13," ") | S13: =IFERROR(IF(OR(A4=61121,A4=61123,A4=64445001,A4=64445002),IF(L8="内掛",ROUNDDOWN(N13*(1-R10),-1),ROUNDDOWN(L13*T10,-1)),IF(L8="内掛",ROUNDDOWN(N13*(1-R10),-2),ROUNDDOWN(L13*T10,-2)))," ") | AA13: 61114 | AB13: ﾓﾊﾞﾗﾌｺｸｼｬ | AC13: ㈱茂原富国社 | AD13: 297-0029 | AE13: 千葉県 茂原市 高師1671 | AF13: 0475-25-0325
B14: =IFERROR(VLOOKUP(A14,商品コード!A:C,2,FALSE)," ") | G14: =O16 -> 0 | K14: → | L14: =IF(A14="","",VLOOKUP(A14,商品コード!A:C,3,FALSE)) | N14: =IFERROR(IF(A4=61121,ROUNDDOWN((L14*P10),-1),IF(A4=61123,ROUNDDOWN((L14*P10),-1),IF(A4=64445001,ROUNDDOWN((L14*P10),-1),IF(A4=64445002,ROUNDDOWN((L14*P10),-1),ROUNDDOWN(L14*P10,-2)))))," ") | Q14: =IFERROR(S14-N14," ") | S14: =IFERROR(IF(OR(A4=61121,A4=61123,A4=64445001,A4=64445002),IF(L8="内掛",ROUNDDOWN(N14*(1-R10),-1),ROUNDDOWN(L14*T10,-1)),IF(L8="内掛",ROUNDDOWN(N14*(1-R10),-2),ROUNDDOWN(L14*T10,-2)))," ") | AA14: 61115 | AB14: ｲﾊﾞﾗｷﾘｮｳﾉｳ | AC14: 茨城菱農㈱ | AD14: 300-4201 | AE14: 茨城県 つくば市 寺具1332-9 | AF14: 0298-69-1045
B15: =IFERROR(VLOOKUP(A15,商品コード!A:C,2,FALSE)," ") | G15: =O17 -> 0 | AA15: 61116 | AB15: ｶﾝﾄｳｺｳｼﾝｸﾎﾞﾀｲﾊﾞﾗｷｼﾞﾑｼｮ | AC15: ㈱関東甲信クボタ 茨城事務所 | AD15: 300-2402 | AE15: 茨城県 つくばみらい市 坂野新田12-42 | AF15: 0297-52-1111
B16: =IFERROR(VLOOKUP(A16,商品コード!A:C,2,FALSE)," ") | G16: =O18 -> 0 | AA16: 61117 | AB16: ｵｵｶﾜｷｶｲ | AC16: 大川機械 | AD16: 300-0024 | AE16: 茨城県 土浦市 田村町988-2 | AF16: 0298-28-0755
A17: 倉庫（ | B17: 033 | C17: ） | D17: 運賃 | E17: 元払い | F17: 伝票NO： | AA17: 61118 | AB17: ﾐﾂﾋﾞｼﾉｳｷﾊﾝﾊﾞｲｲﾊﾞﾗｷｼﾃﾝ | AC17: 三菱農機販売㈱ 茨城支店 | AD17: 311-0133 | AE17: 茨城県 那珂市 鴻巣1135-1 | AF17: 0293-53-2140
E18: 立 元 | F18: 出荷確認 | H18: 受注可否検討 | J18: 連絡書作成 | AA18: 61120 | AB18: ｼﾏｻﾉｳｷ | AC18: ㈱嶋田農機 | AD18: 300-3544 | AE18: 茨城県 結城郡 八千代町 若996 | AF18: 0296-48-1025
E19: 着払い | F19: 承認 | H19: 承認 | J19: 作成者 | AA19: 61121 | AB19: ｸﾎﾞﾀｲﾊﾞﾗｷｹﾝｴｲｷﾞｮｳﾀﾝﾄｳ | AC19: ㈱クボタ 茨城県営業担当 | AD19: 338-0832 | AE19: 埼玉県 さいたま市 桜区 西堀5-2-36 | AF19: 048-862-1125
C20: 便名： | D20: 福山便 西濃便 JPロジ | AA20: 61122 | AB20: ﾅﾘﾀｶﾄｳﾉｳｷ | AC20: 成田加藤農機（有） | AD20: 286-0021 | AE20: 千葉県 成田市 土屋1375-1 | AF20: 0476-22-0579
AA21: 61123 | AB21: ｸﾎﾞﾀﾄﾁｷﾞｹﾝｴｲｷﾞｮｳﾀﾝﾄｳ | AC21: ㈱クボタ 栃木県営業担当 | AD21: 338-0832 | AE21: 埼玉県 さいたま市 桜区 西堀5-2-36 | AF21: 048-862-1125
AA22: 61124 | AB22: ﾈﾓﾄｼｮｳｶｲ | AC22: ㈲根本商会 | AD22: 286-0801 | AE22: 千葉県 成田市 竜台468 | AF22: 0476-37-1211
A23: （様式：EL-97A03） | D23: 【 値引 】 | AA23: 61125 | AB23: ﾏﾙﾃﾝｻﾝｷﾞｮｳｷｶｲ | AC23: マルテン産業機械㈱ | AD23: 293-0001 | AE23: 千葉県 富津市 大堀1434 | AF23: 0439-87-0052
A24: 引き合い内容連絡書 | J24: 株式会社オーレック | AA24: 61126 | AB24: ﾐﾂﾋﾞｼﾉｳｷﾊﾝﾊﾞｲﾁﾊﾞｼﾃﾝ | AC24: 三菱農機販売㈱ 千葉支店 | AD24: 300-1312 | AE24: 茨城県 稲敷郡 河内町 長竿字西の町1596-2 | AF24: 0297-63-4633
A25: 得意先NO： | B25: 得意先名 及び 担当者名： | I25: 受注日： | AA25: 61127 | AB25: ｸﾎﾞﾀｸﾞﾝﾏｹﾝｴｲｷﾞｮｳﾀﾝﾄｳ | AC25: ㈱クボタ 群馬県営業担当 | AD25: 338-0832 | AE25: 埼玉県 さいたま市 桜区 西堀5-2-36 | AF25: 048-862-1125
A26: =A4 -> 0 | C26: =C4 | I26: =I4 -> 45957 | AA26: 61133 | AB26: ﾏｷﾀﾇﾏﾂﾞﾋｶﾞｼﾆﾎﾝ | AC26: ㈱マキタ沼津 東日本支店 | AD26: 362-0031 | AE26: 埼玉県 上尾市 東町2-8-4 | AF26: 048-779-2262
A27: 納入先NO： | B27: 納入先名及び 担当者名： | I27: 出荷希望日： | AA27: 61134 | AB27: ｸﾎﾞﾀｹﾝｷｼﾞｬﾊﾟﾝﾁﾊﾞｴｲｷﾞｮｳｼｮ | AC27: ㈱クボタ建機ジャパン千葉営業所 | AD27: 283-0823 | AE27: 千葉県 東金市 山田 字新田1201-10 | AF27: 茨城菱農
A28: =A6 -> 61344 | C28: =C6 -> ㈲土子機械店 | I28: =I6 -> 45986 | AA28: 61135 | AB28: ｵｵｻﾜｷｶｲ | AC28: 大沢機械 | AD28: 191-0043 | AE28: 東京都 日野市 平山6-2-1 | AF28: 042-591-1588
B29: 住所： | I29: TEL | AA29: 61136 | AB29: ｼﾊﾞﾀ | AC29: ㈱シバタ | AD29: 104-0032 | AE29: 東京都 中央区 八丁堀4-3-1 | AF29: 03-3552-0381
AA30: 61140 | AB30: ﾏｷﾀﾇﾏﾂﾞｷﾞｮｳﾑﾌﾞｼｮｳﾋﾝｶ | AC30: ㈱マキタ沼津 業務部商品課 | AD30: 410-0022 | AE30: 静岡県 沼津市 大岡35 | AF30: 055-963-1112
AA31: 61301 | AB31: ｶﾅｴｻﾝｷﾞｮｳ | AC31: カナエ産業㈱ | AD31: 194-0215 | AE31: 東京都 町田市 小山ケ丘3-7-10 | AF31: 042-798-7181
A32: 商品番号 | B32: 商品名 | E32: 数量 | F32: 値引後(仕切) | H32: 単価 | J32: 合計 | AA32: 61302 | AB32: ﾖｼｻﾞﾜｹﾞﾝﾄﾞｳｷ | AC32: 吉澤原動機 | AD32: 114-0013 | AE32: 東京都 北区 東田端2-8-6 | AF32: 03-3810-2700
A33: =A11 -> 0353-0260 | B33: =B11 -> SP853A/Y | E33: =E11 -> 1 | F33: =S11 | H33: =IFERROR(Q11," ") | J33: =IFERROR(H33*E33," ") | AA33: 61303 | AB33: ﾐﾔｼﾞｷｶｲ | AC33: ㈱宮地機械（出荷停止） | AD33: 177-0033 | AE33: 東京都 練馬区 高野台4-11-28 | AF33: 03-3997-3155
A34: =A12 -> 0 | B34: =B12 | E34: =E12 -> 0 | F34: =S12 | H34: =IFERROR(Q12," ") | J34: =IFERROR(H34*E34," ") | AA34: 61304 | AB34: ﾊﾁｷﾞｮｳｼｮｳｼﾞ | AC34: 八丈商事 | AD34: 100-1401 | AE34: 東京都 八丈島 八丈町 大賀郷1098-2 | AF34: 04996-2-2189
A35: =A13 -> 0 | B35: =B13 | E35: =E13 -> 0 | F35: =S13 | H35: =IFERROR(Q13," ") | J35: =IFERROR(H35*E35," ") | AA35: 61305 | AB35: ｲｼｲﾃﾞﾝｷｼｮｳﾃﾝ | AC35: ㈱石井電気商店 | AD35: 294-0042 | AE35: 千葉県 館山市 上野原294-5 | AF35: 0470-22-0542
A36: =A14 -> 0 | B36: =B14 | E36: =E14 -> 0 | F36: =S14 | H36: =IFERROR(Q14," ") | J36: =IFERROR(H36*E36," ") | AA36: 61306 | AB36: ｲｺﾞｳﾉｳｷ | AC36: ㈲井合農機店 | AD36: 273-0047 | AE36: 千葉県 船橋市 藤原5-22-31 | AF36: 047-439-5477
A37: =A15 -> 0 | B37: =B15 | E37: =E15 -> 0 | F37: =S15 -> 0 | H37: =IFERROR(-(S17)," ") -> 0 | J37: =IFERROR(H37*E37," ") -> 0 | AA37: 61307 | AB37: ｲｼｲﾃｯｺｳ | AC37: 石井鉄工㈱ | AD37: 299-4218 | AE37: 千葉県 長生郡 白子町 関4549-2 | AF37: 0475-33-3528
A38: =A16 -> 0 | B38: =B16 | E38: =E16 -> 0 | F38: =Q18 -> 0 | H38: =IFERROR(-(S18)," ") -> 0 | J38: =IFERROR(H38*E38," ") -> 0 | AA38: 61308 | AB38: ｲﾉｳｴﾉｳｷｼｮｳｶｲ | AC38: ㈲井上農機商会 | AD38: 299-4501 | AE38: 千葉県 いすみ市 岬町椎木1793 | AF38: 0470-87-2823
A39: 税抜小売 | B39: 掛率 | C39: 単価 | D39: OBIC照合 | F39: 伝票NO： | H39: 合計 | J39: =SUM(J33:J36) -> 0 | AA39: 61309 | AB39: ｵｵﾏﾁﾉｳｷ | AC39: ㈲大町農機 | AD39: 272-0801 | AE39: 千葉県 市川市 大町453 | AF39: 047-338-1210
A40: =L11 -> 308000 | B40: =T10 -> #VALUE! | C40: =F33 | D40: =IFERROR((E33*C40)," ") | F40: 出荷確認 | H40: 受注可否検討 | J40: 連絡書作成 | AA40: 61310 | AB40: ｲｼﾞﾏｼｮｳﾃﾝ | AC40: ㈲木嶋商店 | AD40: 289-1115 | AE40: 千葉県 八街市 八街ほ377 | AF40: 0434-44-2481
...

Sheet 部品値引
A1: （様式：EL-97A03）
A2: 引き合い内容連絡書 | J2: 株式会社オーレック
A3: 得意先NO： | B3: 得意先名 及び 担当者名： | I3: 受注日：
A4: 63322 | C4: =IFERROR(VLOOKUP(A4,請求先!A:D,2,FALSE)," ") -> 栃木県農業機械商業協同組合 | I4: =TODAY() -> 46201 | L4: 製品コード検索
A5: 納入先NO： | B5: 納入先名及び 担当者名： | G5: 生産日 | I5: 出荷希望日： | L5: HR532X/M | Q5: → | R5: =IFERROR(VLOOKUP(L5,商品コード!B:F,5,FALSE)," ") -> 0256-0420
A6: 69009039 | C6: =IFERROR(VLOOKUP(A6,出荷先!A:F,3,FALSE)," ") -> 片柳農機具店 | I6: 45348
B7: 住所： | C7: 〒 | D7: =IFERROR(VLOOKUP(A6,出荷先!A:F,4,FALSE)," ") -> 324-0234 | I7: TEL | L7: 実演機対応値引 | Q7: =IF(Q6="","",VLOOKUP(Q6,#REF!,2,FALSE))
B8: =IFERROR(VLOOKUP(A6,出荷先!A:F,5,FALSE)," ") -> 栃木県 大田原市 前田142 | I8: =IFERROR(VLOOKUP(A6,出荷先!A:F,6,FALSE)," ") -> 0287-54-2115 | L8: =IF(L7="","",VLOOKUP(L7,商品コード!A:B,2,FALSE)) -> 外掛 | M8: =IF(I8="","",VLOOKUP(I8,商品コード!#REF!,2,FALSE)) -> #REF! | N8: 10 | P8: %
A10: 商品番号 | B10: 商品名 | E10: 数量 | F10: 単位 | G10: 単価 | I10: オーダーＮｏ 等 | L10: 税別小売 | N10: 通常 | P10: =IF(A4="","",VLOOKUP(A4,請求先!A:D,4,FALSE)) -> 0.65 | Q10: 値引 | R10: =$N$8/100 -> 0.1 | S10: 最終 | T10: =IF(L8="外掛",P10-R10,IF(L8="内掛",ROUNDDOWN(P10*(100-100*R10)%,5))) -> 0.55
A11: 0327-74510 | B11: =IFERROR(VLOOKUP(A11,商品コード!A:C,2,FALSE)," ") -> キャブ調整工具 | E11: 3 | G11: =O13 -> 0 | I11: 即売会注文分 | K11: → | L11: =IF(A11="","",VLOOKUP(A11,商品コード!A:C,3,FALSE)) -> 2500 | N11: =L11*P10 -> 1625 | Q11: =IFERROR(S11-N11," ") -> -250 | S11: =ROUNDDOWN(L11*T10,0) -> 1375
B12: =IFERROR(VLOOKUP(A12,商品コード!A:C,2,FALSE)," ") | G12: =O14 -> 0 | K12: → | L12: =IF(A12="","",VLOOKUP(A12,商品コード!A:C,3,FALSE)) | N12: =IFERROR(IF(A4=61121,ROUNDDOWN((L12*P10),-1),IF(A4=61123,ROUNDDOWN((L12*P10),-1),IF(A4=64445001,ROUNDDOWN((L12*P10),-1),IF(A4=64445002,ROUNDDOWN((L12*P10),-1),ROUNDDOWN(L12*P10,-2)))))," ") | Q12: =IFERROR(S12-N12," ") | S12: =IFERROR(IF(OR(A4=61121,A4=61123,A4=64445001,A4=64445002),IF(L8="内掛",ROUNDDOWN(N12*(1-R10),-1),ROUNDDOWN(L12*T10,-1)),IF(L9="内掛",ROUNDDOWN(N12*(1-R10),-2),ROUNDDOWN(L12*T10,-2)))," ")
B13: =IFERROR(VLOOKUP(A13,商品コード!A:C,2,FALSE)," ") | G13: =O15 -> 0 | K13: → | L13: =IF(A13="","",VLOOKUP(A13,商品コード!A:C,3,FALSE)) | N13: =IFERROR(IF(A4=61121,ROUNDDOWN((L13*P10),-1),IF(A4=61123,ROUNDDOWN((L13*P10),-1),IF(A4=64445001,ROUNDDOWN((L13*P10),-1),IF(A4=64445002,ROUNDDOWN((L13*P10),-1),ROUNDDOWN(L13*P10,-2)))))," ") | Q13: =IFERROR(S13-N13," ") | S13: =IFERROR(IF(OR(A4=61121,A4=61123,A4=64445001,A4=64445002),IF(L8="内掛",ROUNDDOWN(N13*(1-R10),-1),ROUNDDOWN(L13*T10,-1)),IF(L10="内掛",ROUNDDOWN(N13*(1-R10),-2),ROUNDDOWN(L13*T10,-2)))," ")
B14: =IFERROR(VLOOKUP(A14,商品コード!A:C,2,FALSE)," ") | G14: =O16 -> 0 | K14: → | L14: =IF(A14="","",VLOOKUP(A14,商品コード!A:C,3,FALSE)) | N14: =IFERROR(IF(A4=61121,ROUNDDOWN((L14*P10),-1),IF(A4=61123,ROUNDDOWN((L14*P10),-1),IF(A4=64445001,ROUNDDOWN((L14*P10),-1),IF(A4=64445002,ROUNDDOWN((L14*P10),-1),ROUNDDOWN(L14*P10,-2)))))," ") | Q14: =IFERROR(S14-N14," ") | S14: =IFERROR(IF(OR(A4=61121,A4=61123,A4=64445001,A4=64445002),IF(L8="内掛",ROUNDDOWN(N14*(1-R10),-1),ROUNDDOWN(L14*T10,-1)),IF(L10="内掛",ROUNDDOWN(N14*(1-R10),-2),ROUNDDOWN(L14*T10,-2)))," ")
B15: =IFERROR(VLOOKUP(A15,商品コード!A:C,2,FALSE)," ") | G15: =O17 -> 0
B16: =IFERROR(VLOOKUP(A16,商品コード!A:C,2,FALSE)," ") | G16: =O18 -> 0
A17: 倉庫（ | B17: 031 | C17: ） | D17: 運賃 | E17: 元払い | F17: 伝票NO：
E18: 立 元 | F18: 出荷確認 | H18: 受注可否検討 | J18: 連絡書作成
A19: 機番 | E19: 着払い | F19: 承認 | H19: 承認 | J19: 作成者
C20: 便名： | D20: 福山便 西濃便 JPロジ
A23: （様式：EL-97A03） | D23: 【 値引 】
A24: 引き合い内容連絡書 | J24: 株式会社オーレック
A25: 得意先NO： | B25: 得意先名 及び 担当者名： | I25: 受注日：
A26: =A4 -> 63322 | C26: =C4 -> 栃木県農業機械商業協同組合 | I26: =I4 -> 46201
A27: 納入先NO： | B27: 納入先名及び 担当者名： | I27: 出荷希望日：
A28: =A6 -> 69009039 | C28: =C6 -> 片柳農機具店 | I28: =I6 -> 45348
B29: 住所： | I29: TEL
A32: 商品番号 | B32: 商品名 | E32: 数量 | F32: 値引後(仕切) | H32: 単価 | J32: 合計
A33: =A11 -> 0327-74510 | B33: =B11 -> キャブ調整工具 | E33: =E11 -> 3 | F33: =S11 -> 1375 | H33: =IFERROR(Q11," ") -> -250 | J33: =IFERROR(H33*E33," ") -> -750
A34: =A12 -> 0 | E34: =E12 -> 0 | F34: =S12 | H34: =IFERROR(Q12," ") | J34: =IFERROR(H34*E34," ")
A35: =A13 -> 0 | E35: =E13 -> 0 | F35: =S13 | H35: =IFERROR(Q13," ") | J35: =IFERROR(H35*E35," ")
A36: =A14 -> 0 | B36: =B14 | E36: =E14 -> 0 | F36: =S14 | H36: =IFERROR(Q14," ") | J36: =IFERROR(H36*E36," ")
A37: =A15 -> 0 | B37: =B15 | E37: =E15 -> 0 | F37: =S15 -> 0 | H37: =IFERROR(-(S17)," ") -> 0 | J37: =IFERROR(H37*E37," ") -> 0
A38: =A16 -> 0 | B38: =B16 | E38: =E16 -> 0 | F38: =Q18 -> 0 | H38: =IFERROR(-(S18)," ") -> 0 | J38: =IFERROR(H38*E38," ") -> 0
A39: 税抜小売 | B39: 掛率 | C39: 単価 | D39: OBIC照合 | F39: 伝票NO： | H39: 合計 | J39: =SUM(J33:J36) -> -750
A40: =L11 -> 2500 | B40: =T10 -> 0.55 | C40: =F33 -> 1375 | D40: =IFERROR((E33*C40)," ") -> 4125 | F40: 出荷確認 | H40: 受注可否検討 | J40: 連絡書作成
A41: =L12 | B41: =T10 -> 0.55 | C41: =F34 | D41: =IFERROR((E34*C41)," ") | F41: 承認 | H41: 承認 | J41: 作成者
A42: =L13 | B42: =T10 -> 0.55 | C42: =F35 | D42: =IFERROR((E35*C42)," ") | E42: OBIC計
A43: =L14 | B43: =T10 -> 0.55 | C43: =F36 | D43: =IFERROR((E36*C43)," ") | E43: =SUM(D40:D43) -> 4125
A44: 値引理由； | B44: =L7 -> 実演機対応値引 | C44: =N8/100 -> 0.1 | D44: 通常仕切； | E44: =IFERROR(VLOOKUP(A4,請求先!A:D,4,FALSE)," ") -> 0.65

Sheet 引合書
A1: （様式：EL-97A03） | S1: 納入先コード | T1: 納入先カナ名 | U1: 納入先正式名 | V1: 郵便番号1 | W1: 住所1 | X1: 電話番号1-1
A2: 引き合い内容連絡書 | J2: 株式会社オーレック | S2: 61102 | T2: ﾆﾎﾝｸﾘﾝﾄﾝ | U2: 日本クリントン㈱ | V2: 121-0836 | W2: 東京都 足立区 入谷5-7-8 | X2: 03-3854-8221
A3: 得意先NO： | B3: 得意先名 及び 担当者名： | I3: 受注日： | S3: 61103 | T3: ﾄｳｺｳｻﾝｷﾞｮｳ | U3: 東興産業㈱ | V3: 350-0821 | W3: 埼玉県 川越市 福田239 | X3: 0492-23-1217
A4: 61110011 | C4: =IFERROR(VLOOKUP(A4,請求先!A:D,2,FALSE)," ") -> （株）関東甲信クボタ 君津営業所 | I4: 45873 | S4: 61105 | T4: ｲﾄｳｻﾝｷﾞｮｳｷｶｲ | U4: 伊藤産業機械㈱ | V4: 290-0034 | W4: 千葉県 市原市 島野1978 | X4: 0436-22-1743
A5: 納入先NO： | B5: 納入先名及び 担当者名： | G5: 生産日 | I5: 出荷希望日： | S5: 61106 | T5: ｴﾑｴｽｹｰﾉｳｷﾞｮｳｷｶｲﾁﾊﾞｼﾞｷﾞｮｳｼｮ | U5: MSK東急機械㈱ 千葉事業所 | V5: 290-0012 | W5: 千葉県 市原市 藤井3-310 | X5: 0436-41-1069
A6: 61110011 | C6: =IFERROR(VLOOKUP(A6,出荷先!A:F,3,FALSE)," ") -> ㈱関東甲信クボタ 君津営業所 | I6: 45873 | S6: 61107 | T6: ｻｻｷｼｮｳｶｲ | U6: ㈱佐々木商会 | V6: 294-0037 | W6: 千葉県 館山市 長須賀123 | X6: 0470-22-1166
B7: 住所： | C7: 〒 | D7: =IFERROR(VLOOKUP(A6,出荷先!A:F,4,FALSE)," ") -> 292-0403 | I7: TEL | S7: 61108 | T7: ｽｷﾞｷﾃｯｺｳ | U7: 杉木鉄工㈱ | V7: 297-0029 | W7: 千葉県 茂原市 高師1536 | X7: 0475-22-4587
B8: =IFERROR(VLOOKUP(A6,出荷先!A:F,5,FALSE)," ") -> 千葉県 君津市 三田123-6 | I8: =IFERROR(VLOOKUP(A6,出荷先!A:F,6,FALSE)," ") -> 0439-29-6301 | S8: 61109 | T8: ﾀｶﾉｻﾝｷﾞｮｳ | U8: 高野産業㈱ | V8: 292-0054 | W8: 千葉県 木更津市 長須賀924-1 | X8: 0438-22-6251
S9: 61110 | T9: ｶﾝﾄｳｺｼﾝｸﾎﾞﾀﾁﾊﾞｼﾞｷﾞｮｳﾌﾞ | U9: ㈱関東甲信クボタ 南関東事業所 | V9: 260-0808 | W9: 千葉県 千葉市 中央区 星久喜町176-4 | X9: 043-261-3131
A10: 商品番号 | B10: 商品名 | E10: 数量 | F10: 単位 | G10: 単価 | I10: オーダーＮｏ 等 | S10: 61111 | T10: ﾅｶﾔｼｮｳｶｲ | U10: ㈱中屋商会 | V10: 289-2146 | W10: 千葉県 匝瑳市 八日市場ホ452 | X10: 0479-72-1161
A11: 89-1113-060182 | B11: =IFERROR(VLOOKUP(A11,商品コード!A:C,2,FALSE)," ") -> 六角ﾎﾞﾙﾄ(8T) M6*18 | E11: 1 | S11: 61112 | T11: ﾅｶﾑﾗｻﾝｷﾞｮｳ | U11: ㈱中村産業 | V11: 283-0811 | W11: 千葉県 東金市 台方246 | X11: 0475-52-2615
A12: 0353-71210 | B12: =IFERROR(VLOOKUP(A12,商品コード!A:C,2,FALSE)," ") -> 変速ワイヤー | E12: 1 | S12: 61113 | T12: ﾌﾀﾊﾞｺｳｷ | U12: ㈲双葉工機 | V12: 270-2222 | W12: 千葉県 松戸市 高塚新田340-11 | X12: 0473-92-7256
A13: 0353-2051H | B13: =IFERROR(VLOOKUP(A13,商品コード!A:C,2,FALSE)," ") -> 刈高さ調整フレーム | E13: 1 | S13: 61114 | T13: ﾓﾊﾞﾗﾌｺｸｼｬ | U13: ㈱茂原富国社 | V13: 297-0029 | W13: 千葉県 茂原市 高師1671 | X13: 0475-25-0325
A14: 0353-01800 | B14: =IFERROR(VLOOKUP(A14,商品コード!A:C,2,FALSE)," ") -> 変速ｱｰﾑ | E14: 1 | S14: 61115 | T14: ｲﾊﾞﾗｷﾘｮｳﾉｳ | U14: 茨城菱農㈱ | V14: 300-4201 | W14: 茨城県 つくば市 寺具1332-9 | X14: 0298-69-1045
A15: 89-1511-060042 | B15: =IFERROR(VLOOKUP(A15,商品コード!A:C,2,FALSE)," ") -> 六角ﾅｯﾄ M6 | E15: 1 | S15: 61116 | T15: ｶﾝﾄｳｺｳｼﾝｸﾎﾞﾀｲﾊﾞﾗｷｼﾞﾑｼｮ | U15: ㈱関東甲信クボタ 茨城事務所 | V15: 300-2402 | W15: 茨城県 つくばみらい市 坂野新田12-42 | X15: 0297-52-1111
B16: =IFERROR(VLOOKUP(A16,商品コード!A:C,2,FALSE)," ") | S16: 61117 | T16: ｵｵｶﾜｷｶｲ | U16: 大川機械 | V16: 300-0024 | W16: 茨城県 土浦市 田村町988-2 | X16: 0298-28-0755
A17: 倉庫（ | B17: 001 | C17: ） | D17: 運賃 | E17: 元払い | F17: 伝票NO： | S17: 61118 | T17: ﾐﾂﾋﾞｼﾉｳｷﾊﾝﾊﾞｲｲﾊﾞﾗｷｼﾃﾝ | U17: 三菱農機販売㈱ 茨城支店 | V17: 311-0133 | W17: 茨城県 那珂市 鴻巣1135-1 | X17: 0293-53-2140
B18: 0 | E18: 立 元 | F18: 出荷確認 | H18: 受注可否検討 | J18: 連絡書作成 | S18: 61120 | T18: ｼﾏｻﾉｳｷ | U18: ㈱嶋田農機 | V18: 300-3544 | W18: 茨城県 結城郡 八千代町 若996 | X18: 0296-48-1025
A19: 鶴岡担当 SP853 不具合対応のため | E19: 着払い | F19: 承認 | H19: 承認 | J19: 作成者 | S19: 61121 | T19: ｸﾎﾞﾀｲﾊﾞﾗｷｹﾝｴｲｷﾞｮｳﾀﾝﾄｳ | U19: ㈱クボタ 茨城県営業担当 | V19: 338-0832 | W19: 埼玉県 さいたま市 桜区 西堀5-2-36 | X19: 048-862-1125
C20: 便名： | D20: 福山便 西濃便 JPロジ | S20: 61122 | T20: ﾅﾘﾀｶﾄｳﾉｳｷ | U20: 成田加藤農機（有） | V20: 286-0021 | W20: 千葉県 成田市 土屋1375-1 | X20: 0476-22-0579
S21: 61123 | T21: ｸﾎﾞﾀﾄﾁｷﾞｹﾝｴｲｷﾞｮｳﾀﾝﾄｳ | U21: ㈱クボタ 栃木県営業担当 | V21: 338-0832 | W21: 埼玉県 さいたま市 桜区 西堀5-2-36 | X21: 048-862-1125
S22: 61124 | T22: ﾈﾓﾄｼｮｳｶｲ | U22: ㈲根本商会 | V22: 286-0801 | W22: 千葉県 成田市 竜台468 | X22: 0476-37-1211
A23: 製品コード検索 | S23: 61125 | T23: ﾏﾙﾃﾝｻﾝｷﾞｮｳｷｶｲ | U23: マルテン産業機械㈱ | V23: 293-0001 | W23: 千葉県 富津市 大堀1434 | X23: 0439-87-0052
A24: RCSP530/Y | F24: → | G24: =IFERROR(VLOOKUP(A24,商品コード!B:F,5,FALSE)," ") | S24: 61126 | T24: ﾐﾂﾋﾞｼﾉｳｷﾊﾝﾊﾞｲﾁﾊﾞｼﾃﾝ | U24: 三菱農機販売㈱ 千葉支店 | V24: 300-1312 | W24: 茨城県 稲敷郡 河内町 長竿字西の町1596-2 | X24: 0297-63-4633
S25: 61127 | T25: ｸﾎﾞﾀｸﾞﾝﾏｹﾝｴｲｷﾞｮｳﾀﾝﾄｳ | U25: ㈱クボタ 群馬県営業担当 | V25: 338-0832 | W25: 埼玉県 さいたま市 桜区 西堀5-2-36 | X25: 048-862-1125
S26: 61133 | T26: ﾏｷﾀﾇﾏﾂﾞﾋｶﾞｼﾆﾎﾝ | U26: ㈱マキタ沼津 東日本支店 | V26: 362-0031 | W26: 埼玉県 上尾市 東町2-8-4 | X26: 048-779-2262
S27: 61134 | T27: ｸﾎﾞﾀｹﾝｷｼﾞｬﾊﾟﾝﾁﾊﾞｴｲｷﾞｮｳｼｮ | U27: ㈱クボタ建機ジャパン千葉営業所 | V27: 283-0823 | W27: 千葉県 東金市 山田 字新田1201-10 | X27: 茨城菱農
S28: 61135 | T28: ｵｵｻﾜｷｶｲ | U28: 大沢機械 | V28: 191-0043 | W28: 東京都 日野市 平山6-2-1 | X28: 042-591-1588
S29: 61136 | T29: ｼﾊﾞﾀ | U29: ㈱シバタ | V29: 104-0032 | W29: 東京都 中央区 八丁堀4-3-1 | X29: 03-3552-0381
S30: 61140 | T30: ﾏｷﾀﾇﾏﾂﾞｷﾞｮｳﾑﾌﾞｼｮｳﾋﾝｶ | U30: ㈱マキタ沼津 業務部商品課 | V30: 410-0022 | W30: 静岡県 沼津市 大岡35 | X30: 055-963-1112
S31: 61301 | T31: ｶﾅｴｻﾝｷﾞｮｳ | U31: カナエ産業㈱ | V31: 194-0215 | W31: 東京都 町田市 小山ケ丘3-7-10 | X31: 042-798-7181
S32: 61302 | T32: ﾖｼｻﾞﾜｹﾞﾝﾄﾞｳｷ | U32: 吉澤原動機 | V32: 114-0013 | W32: 東京都 北区 東田端2-8-6 | X32: 03-3810-2700
S33: 61303 | T33: ﾐﾔｼﾞｷｶｲ | U33: ㈱宮地機械（出荷停止） | V33: 177-0033 | W33: 東京都 練馬区 高野台4-11-28 | X33: 03-3997-3155
S34: 61304 | T34: ﾊﾁｷﾞｮｳｼｮｳｼﾞ | U34: 八丈商事 | V34: 100-1401 | W34: 東京都 八丈島 八丈町 大賀郷1098-2 | X34: 04996-2-2189
S35: 61305 | T35: ｲｼｲﾃﾞﾝｷｼｮｳﾃﾝ | U35: ㈱石井電気商店 | V35: 294-0042 | W35: 千葉県 館山市 上野原294-5 | X35: 0470-22-0542
S36: 61306 | T36: ｲｺﾞｳﾉｳｷ | U36: ㈲井合農機店 | V36: 273-0047 | W36: 千葉県 船橋市 藤原5-22-31 | X36: 047-439-5477
... S95: 61376 | T95: ﾘｮｳｴｲｼｬ | U95: ㈲良栄社商会 | V95: 299-1151 | W95: 千葉県 君津市 中野4-15-18 | X95: 0439-52-0035
T96: ｺｼﾞﾝｷｬｸ | U96: 個人客
S97: 61400 | T97: ｺﾐﾔﾉｳｻﾝｷｼｮｳｶｲ | U97: ㈲古宮農蚕機商会 | V97: 192-0051 | W97: 東京都 八王子市 元本郷町1-5-5 | X97: 042-625-2328
S98: 63102 | T98: ﾐﾂﾋﾞｼﾉｳｷﾊﾝﾊﾞｲｶﾝﾄｳｺｳｼﾝｴﾂ | U98: 三菱農機販売㈱ 関東甲信越支店 | V98: 340-0203 | W98: 埼玉県 久喜市 桜田2-133-4 | X98: 0480-58-9521
...

Sheet 商品コード
A1: 品番コード | B1: 品番名 | C1: 新小売単価(2023.1.1～) | D1: やまびこ運賃 | E1: ｲﾘﾉ値引 | F1: 品番コード | J1: データ引用2022/04/01
A2: 実演機値引 | B2: 外掛 | F2: 実演機値引
A3: 実演機対応値引 | B3: 外掛 | F3: 実演機対応値引
A4: 展示機値引 | B4: 内掛 | F4: 展示機値引
A5: 不需要期値引 | B5: 内掛 | F5: 不需要期値引
A6: 早期確注値引 | B6: 内掛 | F6: 早期確注値引
A7: 台数値引 | B7: 内掛 | F7: 台数値引
A8: 推進値引 | B8: 内掛 | F8: 推進値引
A9: 展示会値引 | B9: 内掛 | F9: 展示会値引
A10: 0353-0020 | B10: SP753B/M | C10: 328000
A11: 0331-0220 | B11: AM63AX/M | C11: 278000 | D11: 7660 | F11: 0331-0220
A12: 0332-0220 | B12: AM63BX/M | C12: 309000 | D12: 7660 | F12: 0332-0220
A13: 0332-0320 | B13: AM64B/M | C13: 396000 | D13: 7660 | F13: 0332-0320
A14: 0333-0220 | B14: AM73BX/M | C14: 367000 | D14: 9200 | F14: 0333-0220
A15: 0333-0320 | B15: AM74B/M | C15: 468000 | D15: 9200 | F15: 0333-0320
A16: 0311-0220 | B16: AM81X/M | C16: 388000 | D16: 14420 | F16: 0311-0220
A17: 0051-0020 | B17: AR301/M | C17: 217000 | D17: 5220 | F17: 0051-0020
A18: 0027-0020 | B18: AR400/M | C18: 228000 | D18: 5220 | F18: 0027-0020
A19: 0036-0220 | B19: AR660/M | C19: 280000 | D19: 4480 | F19: 0036-0220
A20: 0038-0020 | B20: AR604/M | C20: 327000 | D20: 7260 | F20: 0038-0020
A21: 0039-0020 | B21: AR704/M | C21: 366000 | D21: 9200 | F21: 0039-0020
